Workbook

Sheet Feuil1
A3: DATE
A4: CHAUFFEUR
E6: Arrêt 1 | I6: Arrêt 2 | M6: Arrêt 3 | Q6: PEM PASSAMAINTY
B7: Heure théorique départ | C7: Heure réelle départ | D7: Nbre personnes + | E7: Nbre personnes + | F7: Nbre personnes - | G7: Heure arrivée arrêt 1 | H7: Délai | I7: Nbre personnes + | J7: Nbre personnes - | K7: Heure arrivée arrêt 2 | L7: Délai | M7: Nbre personnes + | N7: Nbre personnes - | O7: Heure arrivée arrêt 3 | P7: Délai | Q7: Nbre personnes - | S7: Heure arrivée finale | T7: Commentaires | U7: Temps Aller
A8: VAHIBE | B8: 0.20833333 | H8: =G8-C8 -> 0 | L8: =K8-G8 -> 0 | P8: =O8-K8 -> 0 | R8: =IF(D8+E8-F8+I8-J8+M8-N8=Q8,"OK",D8+E8-F8+I8-J8+M8-N8-Q8) -> OK | U8: =S8-C8 -> 0
A9: VAHIBE | B9: 0.21527778 | H9: =G9-C9 -> 0 | L9: =K9-G9 -> 0 | P9: =O9-K9 -> 0 | U9: =S9-C9 -> 0
A10: VAHIBE | B10: 0.22222222 | H10: =G10-C10 -> 0 | L10: =K10-G10 -> 0 | P10: =O10-K10 -> 0 | U10: =S10-C10 -> 0
A11: VAHIBE | B11: 0.22916667 | H11: =G11-C11 -> 0 | L11: =K11-G11 -> 0 | P11: =O11-K11 -> 0 | U11: =S11-C11 -> 0
A12: VAHIBE | B12: 0.23611111 | H12: =G12-C12 -> 0 | L12: =K12-G12 -> 0 | P12: =O12-K12 -> 0 | U12: =S12-C12 -> 0
A13: VAHIBE | B13: 0.24305556 | H13: =G13-C13 -> 0 | L13: =K13-G13 -> 0 | P13: =O13-K13 -> 0 | U13: =S13-C13 -> 0
A14: VAHIBE | B14: 0.25 | H14: =G14-C14 -> 0 | L14: =K14-G14 -> 0 | P14: =O14-K14 -> 0 | U14: =S14-C14 -> 0
A15: VAHIBE | B15: 0.25694444 | H15: =G15-C15 -> 0 | L15: =K15-G15 -> 0 | P15: =O15-K15 -> 0 | U15: =S15-C15 -> 0
A16: VAHIBE | B16: 0.26388889 | H16: =G16-C16 -> 0 | L16: =K16-G16 -> 0 | P16: =O16-K16 -> 0 | U16: =S16-C16 -> 0
A17: VAHIBE | B17: 0.27083333 | H17: =G17-C17 -> 0 | L17: =K17-G17 -> 0 | P17: =O17-K17 -> 0 | U17: =S17-C17 -> 0
A18: VAHIBE | B18: 0.27777778 | H18: =G18-C18 -> 0 | L18: =K18-G18 -> 0 | P18: =O18-K18 -> 0 | U18: =S18-C18 -> 0
A19: VAHIBE | B19: 0.28472222 | H19: =G19-C19 -> 0 | L19: =K19-G19 -> 0 | P19: =O19-K19 -> 0 | U19: =S19-C19 -> 0
A20: VAHIBE | B20: 0.29166667 | H20: =G20-C20 -> 0 | L20: =K20-G20 -> 0 | P20: =O20-K20 -> 0 | U20: =S20-C20 -> 0
... A26: VAHIBE | B26: 0.33333333 | H26: =G26-C26 -> 0 | L26: =K26-G26 -> 0 | P26: =O26-K26 -> 0 | U26: =S26-C26 -> 0
Q27: VAHIBE | U27: =SUM(U8:U26) -> 0
A28: PEM PASSAMAINTY | B28: 0.625 | H28: =G28-C28 -> 0 | L28: =K28-G28 -> 0 | P28: =O28-K28 -> 0 | U28: =S28-C28 -> 0
A29: PEM PASSAMAINTY | B29: 0.63194444 | H29: =G29-C29 -> 0 | L29: =K29-G29 -> 0 | P29: =O29-K29 -> 0 | U29: =S29-C29 -> 0
A30: PEM PASSAMAINTY | B30: 0.63888889 | H30: =G30-C30 -> 0 | L30: =K30-G30 -> 0 | P30: =O30-K30 -> 0 | U30: =S30-C30 -> 0
A31: PEM PASSAMAINTY | B31: 0.64583333 | H31: =G31-C31 -> 0 | L31: =K31-G31 -> 0 | P31: =O31-K31 -> 0 | U31: =S31-C31 -> 0
A32: PEM PASSAMAINTY | B32: 0.65277778 | H32: =G32-C32 -> 0 | L32: =K32-G32 -> 0 | P32: =O32-K32 -> 0 | U32: =S32-C32 -> 0
A33: PEM PASSAMAINTY | B33: 0.65972222 | H33: =G33-C33 -> 0 | L33: =K33-G33 -> 0 | P33: =O33-K33 -> 0 | U33: =S33-C33 -> 0
A34: PEM PASSAMAINTY | B34: 0.66666667 | H34: =G34-C34 -> 0 | L34: =K34-G34 -> 0 | P34: =O34-K34 -> 0 | U34: =S34-C34 -> 0
A35: PEM PASSAMAINTY | B35: 0.67361111 | H35: =G35-C35 -> 0 | L35: =K35-G35 -> 0 | P35: =O35-K35 -> 0 | U35: =S35-C35 -> 0
A36: PEM PASSAMAINTY | B36: 0.68055556 | H36: =G36-C36 -> 0 | L36: =K36-G36 -> 0 | P36: =O36-K36 -> 0 | U36: =S36-C36 -> 0
A37: PEM PASSAMAINTY | B37: 0.6875 | H37: =G37-C37 -> 0 | L37: =K37-G37 -> 0 | P37: =O37-K37 -> 0 | U37: =S37-C37 -> 0
A38: PEM PASSAMAINTY | B38: 0.69444444 | H38: =G38-C38 -> 0 | L38: =K38-G38 -> 0 | P38: =O38-K38 -> 0 | U38: =S38-C38 -> 0
A39: PEM PASSAMAINTY | B39: 0.70138889 | H39: =G39-C39 -> 0 | L39: =K39-G39 -> 0 | P39: =O39-K39 -> 0 | U39: =S39-C39 -> 0
... A46: PEM PASSAMAINTY | B46: 0.75 | H46: =G46-C46 -> 0 | L46: =K46-G46 -> 0 | P46: =O46-K46 -> 0 | U46: =S46-C46 -> 0
U47: =SUM(U28:U46) -> 0
U48: =U47+U27 -> 0
C49: Signature Chauffeur | I49: Signature Coordinateur

Sheet REUNION DU 28.04
B1: N° | C1: CADEMA | D1: STATUT | E1: LICENCE TRANSPORTEUR | F1: SIREN LICENCE | G1: VALIDITE LICENCE TRANSP | H1: N° | I1: N° Chauffeur | J1: Type | K1: Nom | L1: Prénom | M1: Téléphone | N1: Mail | O1: Siret | P1: Secteur d'activité | Q1: N° licence | R1: CARTE CONDUCTEUR | S1: VALIDITE CARTE CONDUCTEUR | T1: N° IMMATRICULATION CARTE GRISE | U1: DATE IMMATRICULATION | V1: AGE DU VEHICULE | W1: Type de vehicule | X1: ETAT VEHICULE | Y1: RDV MAY EQUIP | Z1: HABILLAGE | AA1: REGLT HABILLAGE | AB1: EQUIPEMENT | AC1: HABILLAGE 2021 | AD1: HABILLAGE 2023 | AE1: IDENTITE | AF1: NATIONALITE | AG1: VALIDITE CARTE SEJOUR | AH1: CARTE VITALE | AI1: ASSURANCES | AJ1: FACTURE _3 MOIS | AK1: IMPOTS | AL1: PHOTO | AM1: N° AGC | AN1: Capital souscrit | AO1: Année de souscription | AP1: Cotisations versées en 2021 | AQ1: COTISATIONS 2023 | AR1: COTISATIONS 2024 | AS1: N° Rue | AT1: Adresse | AU1: Code postal | AV1: Commune | AW1: REMARQUES
A2: 1 | B2: 11 | C2: CADEMA 1 | D2: AO | E2: NON | F2: - | G2: - | H2: 1 | I2: C4 | J2: C2 | K2: ABDOU MINIHADJI | L2: Amada | M2: 0639 65 03 93 | N2: abdouminihadjiamada@hotmail.com | O2: 066 311 101 000 19 | P2: Centre Sud | Q2: 976-CS-057 | R2: 505 | S2: 45305 | T2: FY-654-BF | U2: 44279 | V2: =2024-YEAR(U2) -> 3 | W2: 9 PLACES | X2: BON | Z2: OUI | AA2: _ | AB2: NON | AC2: OUI | AE2: 43262 | AF2: F | AG2: _ | AH2: NON | AI2: NON | AJ2: 2020 | AL2: OUI | AM2: 2020/13 | AN2: 510 | AO2: 43466 | AP2: 450 | AS2: 64 | AT2: Avenue de rassi | AU2: 97670 | AV2: Chiconi | AW2: ancien gérant - Habillage 2021
A3: 33 | B3: 17 | C3: CADEMA 1 | D3: AO | E3: NON | F3: - | G3: - | H3: 2 | I3: C6 | J3: C10 | K3: ADINANI | L3: Zoubert | M3: 0639 25 77 76 | N3: zoubert.adinani2@gmail.com | O3: 799 358 700 00018 | P3: Mamoudzou | Q3: 976-M-447 | R3: 1050 | S3: 46342 | T3: GR-407-DV | U3: 45182 | V3: =2024-YEAR(U3) -> 1 | W3: 9 PLACES | X3: BON | Y3: 45406 | Z3: NON | AA3: OUI | AB3: NON | AC3: NON | AD3: A venir | AE3: 48415 | AF3: F | AG3: _ | AH3: OUI | AI3: OUI | AJ3: OUI | AK3: 2022 | AL3: OUI | AN3: 510 | AO3: 43466 | AP3: 250 | AQ3: NON | AR3: NON | AT3: Tahiti plage route de poroani | AU3: 97640 | AV3: Sada | AW3: attente débolacge prêt
A4: 65 | B4: 23 | C4: CADEMA 1 | D4: AO | E4: NON | F4: - | G4: - | H4: 3 | J4: C14 | K4: ALI ATTOUMANI | L4: Bacar | M4: 0639 87 21 88 | N4: aattoumani.bacar@gmail.com | O4: 024 068 413 00020 | P4: Mamoudzou | Q4: 976-M-116 | R4: 222 | S4: 45489 | T4: FJ-886-VX | U4: 43707 | W4: 9 PLACES | Z4: A MOITIE | AA4: NON | AC4: OUI PAS PAYE | AE4: 45896 | AF4: F | AH4: NON | AI4: NON | AJ4: NON | AK4: NON | AL4: OUI | AN4: 510 | AO4: 43466 | AP4: 150 | AQ4: NON | AR4: NON | AS4: 4 | AT4: Chemin ma ali andy | AU4: 97640 | AV4: Sada | AW4: Voiture endommagé d'un coté et la tete de taxi aussi habillé en 2021
A5: 129 | B5: 35 | C5: CADEMA 1 | D5: AO | E5: NON | F5: - | G5: - | H5: 4 | K5: ALLAOUI | L5: Inzoudine | M5: 0639 075923/0639 26 27 78 | N5: ambdihoumadi976@gmail.com | O5: 024 078 396 000 41 | P5: Mamoudzou | Q5: 976-M-049 | R5: 1294 | S5: 43992 | T5: GH-790-LS | U5: 44753 | V5: =2024-YEAR(U5) -> 2 | W5: 9 PLACES | Y5: ? Pas payé | Z5: NON | AA5: _ | AB5: NON | AE5: 47882 | AF5: F | AG5: _ | AH5: NON | AI5: NON | AJ5: NON | AK5: NON | AL5: NON | AM5: 2020/44 | AN5: 510 | AO5: 43466 | AP5: 450 | AS5: 85 | AT5: Rue younoussa bamana | AU5: 97640 | AV5: Sada | AW5: a une voiture neuve
A6: 161 | B6: 41 | C6: CADEMA 1 | D6: AO | E6: NON | F6: - | G6: - | H6: 5 | I6: voiture en panne | K6: ALLAOUI | L6: Soibrane | M6: 0639 65 31 82 | N6: stt653182@hotmail.com | O6: 024 043 30 000 11 | P6: Centre Sud | Q6: 976-CS-048 | R6: 806 | S6: 43222 | T6: FZ_148_HW | U6: 44336 | V6: =2024-YEAR(U6) -> 3 | W6: 9 PLACES | X6: OK | Y6: ? Pas payé | Z6: NON | AB6: NON | AC6: OUI | AE6: 46556 | AF6: F | AG6: _ | AH6: OUI | AI6: OUI | AJ6: OUI | AK6: OUI | AL6: OUI | AN6: 510 | AP6: 450 | AT6: Quartier Kami case impasse mavandzani | AU6: 97625 | AV6: Kani kéli | AW6: Il est pas eligible pour la demande de subvention
A7: 129 | B7: 35 | C7: CADEMA 1 | D7: AO | E7: NON | F7: - | G7: - | H7: 6 | J7: C6 | K7: AMBDI | L7: Houmadi | M7: 0639 23 55 69 | N7: ambdihoumadi976@gmail.com | O7: 066 312 224 000 26 | P7: Sud | Q7: 976-S-023 | R7: 759 | S7: 45639 | T7: GC-122-QA | U7: 44495 | V7: =2024-YEAR(U7) -> 3 | W7: 9 PLACES | X7: OK | Z7: OUI | AB7: OUI | AD7: OUI | AE7: 48640 | AF7: F | AG7: _ | AH7: OUI | AI7: OUI | AJ7: NON | AK7: 2022 | AL7: OUI | AM7: 2020/46 | AN7: 510 | AO7: 43466 | AP7: 250 | AQ7: NON | AR7: NON | AT7: Route nationale Mbouanatsa | AU7: 97620 | AV7: BOUENI | AW7: Habillage 2023
A8: 193 | B8: 47 | C8: CADEMA 1 | D8: AO | E8: NON | F8: - | G8: - | H8: 7 | I8: C9 | J8: C7 | K8: BINA HALADI | L8: Bina | M8: 0639 06 05 82 | N8: wonamaore@gmail.com | O8: 853 690 428 000 18 | P8: Sud | Q8: 976-S-045 | R8: 1414 | S8: 45181 | T8: GE-883-ES | U8: 44581 | V8: =2024-YEAR(U8) -> 2 | W8: 9 places | Z8: OUI | AA8: _ | AB8: OUI | AD8: OUI | AE8: 45040 | AF8: F | AG8: _ | AH8: OUI | AI8: 2023 | AJ8: OUI | AK8: 2022 | AL8: NON | AM8: 2020/61 | AN8: 510 | AO8: 44285 | AP8: 450 | AS8: 8 | AT8: Rue Said Fatima | AU8: 97640 | AV8: SADA | AW8: Habillage juin 2023
A9: 225 | B9: 53 | C9: CADEMA 1 | D9: AO | E9: NON | F9: - | G9: - | H9: 8 | J9: C12 | K9: BOINARIZIKI | L9: Zena Dhurari | M9: 0639 66 36 94 06 50 45 94 42 | N9: dhurari.transport@gmail.com | O9: 500 894 043 000 16 | P9: Centre Sud | Q9: 976-CS-071 | R9: 1000 | S9: 44349 | T9: FF-569-NF | U9: 43573 | V9: =2024-YEAR(U9) -> 5 | W9: 9 PLACES | Z9: NON | AA9: _ | AB9: NON | AE9: 45177 | AF9: F | AG9: _ | AH9: OUI | AI9: 2023 | AJ9: OUI | AK9: 2022 | AL9: OUI | AN9: 510 | AO9: 43466 | AP9: 250 | AS9: 97 | AT9: Rue du commerce | AU9: 97640 | AV9: Sada | AW9: voiture pas habillée
A10: 257 | B10: 59 | C10: CADEMA 1 | D10: AO | E10: NON | F10: - | G10: - | H10: 9 | I10: C3 | J10: C8 | K10: COMBO | L10: Said | M10: 0639 68 37 93 | N10: combosaid5@gmail.cpm | O10: 054 394 853 00029 | P10: Mamoudzou | Q10: 976-M-164 | R10: 920 | S10: 44871 | T10: GB-965-EQ | U10: 44419 | V10: =2024-YEAR(U10) -> 3 | W10: 9 PLACES | X10: NEUF | Y10: 45411 | Z10: NON | AA10: NON | AB10: NON | AC10: NON | AD10: NON | AE10: 49279 | AF10: F | AG10: _ | AH10: OUI | AI10: OUI | AJ10: 2024 | AK10: 2022 | AL10: NON | AM10: 2020/70 | AN10: 510 | AO10: 44295 | AP10: 100 | AQ10: NON | AR10: NON | AS10: 193 | AT10: Route Départementale | AU10: 97630 | AV10: Mtsamboro | AW10: Il a reçu sa subvention et il a rien payé, et il a utiliser l'argent
A11: 289 | B11: 65 | C11: CADEMA 1 | D11: AO | E11: NON | F11: - | G11: - | H11: 10 | I11: C1 | J11: C1 | K11: EL ANZIZE SALIM | L11: Hamada | M11: 0639 22 81 28 | N11: elsalimhamada@hotmail.com | O11: 024 076 531 00011 | P11: Mamoudzou | Q11: 976_M_209 | R11: 413 | S11: 46877 | T11: GM_515_YL | U11: 45012 | V11: =2024-YEAR(U11) -> 1 | W11: 9 PLACES | Z11: 2023 | AA11: OUI | AB11: 2023 | AD11: OUI | AE11: 10959 | AF11: G | AG11: _ | AH11: NON | AI11: NON | AJ11: NON | AK11: NON | AL11: OUI | AM11: 2022/198 | AN11: 510 | AO11: 43466 | AP11: 250 | AS11: 8 | AT11: Rue de mjinpia | AU11: 97650 | AV11: Mtsangamoudji | AW11: habillage 9 place 2023
A12: 353 | B12: 77 | C12: CADEMA 1 | D12: AO | E12: NON | F12: - | G12: - | H12: 11 | I12: C5 | J12: C16 | K12: HADHURAMI | L12: Makinedine | M12: 0639 94 46 40 | N12: Hadhuramimakinedine976@gmail.com | O12: 054 397 211 00019 | P12: SUD | Q12: 976_S_069 | R12: 150 | S12: 45874 | T12: FZ-411-ZD | U12: 44362 | V12: =2024-YEAR(U12) -> 3 | W12: 9 PLACES | Z12: OUI | AB12: OUI | AD12: OUI | AE12: 49522 | AF12: F | AG12: _ | AH12: OUI | AI12: 2023 | AJ12: NON | AK12: 2022 | AL12: OUI | AM12: 2020/82 | AN12: 510 | AO12: 43466 | AP12: 550 | AS12: 14 | AT12: Rue foundi hamada m'zé | AU12: 97625 | AV12: Kani kéli | AW12: Habillage 2021 aurait 2 véhicules
A13: 385 | B13: 83 | C13: CADEMA 1 | D13: AO | E13: NON | F13: - | G13: - | H13: 12 | J13: C13 | K13: MADI BOINA | L13: Mkidachi | M13: 0639 22 08 67 | N13: madiboinamkidachi@hotmail.com | O13: 500 793 526 00012 | P13: NORD | Q13: 976-N-63 | R13: 985 | S13: 44456 | T13: GS-501-ZK | U13: 45273 | W13: 9 PLACES | X13: NEUF | Y13: pas de vitre | Z13: NON | AA13: OUI | AB13: OUI | AC13: NON | AD13: A venir | AE13: 45248 | AF13: F | AH13: NON | AI13: NON | AJ13: NON | AK13: NON | AL13: NON | AN13: 510 | AO13: 43466 | AP13: 150 | AQ13: NON | AR13: NON | AS13: 27 | AT13: Rue d'andimaka | AU13: 97650 | AV13: Mtsangamouji
A14: 417 | B14: 89 | C14: CADEMA 1 | D14: AO | E14: NON | F14: - | G14: - | H14: 13 | I14: C7 | J14: C3 | K14: MOISSULI HIMIDI | L14: Enly | M14: 0639 94 58 14 | N14: enlymoissuli@gmail.com | O14: 853 881 084 000 18 | P14: NORD | Q14: 976-N-015 | R14: 994 | S14: 44263 | T14: GW-003-JA | U14: 45394 | W14: 9 PLACES | Y14: att May Equip | Z14: NON | AA14: NON | AB14: NON | AC14: NON | AD14: NON | AE14: 47621 | AF14: F | AH14: NON | AI14: NON | AJ14: NON | AK14: NON | AL14: OUI | AN14: 510 | AO14: 43466 | AP14: 200 | AQ14: NON | AR14: NON | AS14: 5 | AT14: Quartier mronobaban sidi , Hamjago | AU14: 97630 | AV14: Mtsamboro | AW14: Il attend sa subvention , justine lui a dit d'aller harceler le CD pour qui'il debloque sa subvention
A15: 97 | B15: 29 | C15: CADEMA 1 | D15: AO | E15: NON | F15: - | G15: - | H15: 14 | I15: soucis de famille | J15: C4 | K15: OUSSENI | L15: Soula | M15: 0639 69 03 87 | N15: soulaousseni415@gmail.com | O15: 066 307 372 000 12 | P15: Centre NORD | Q15: 976-CN-003 | R15: 249 | S15: 43132 | T15: GP_813_HX | U15: 45083 | V15: =2024-YEAR(U15) -> 1 | W15: 9 PLACES | X15: TBE | Z15: 2023 | AA15: OUI | AB15: 2023 | AD15: OUI | AE15: 49496 | AF15: F | AG15: _ | AH15: OUI | AI15: OUI | AJ15: OUI | AK15: OUI | AL15: OUI | AM15: 2021/181 | AN15: 510 | AO15: 43466 | AP15: 300 | AS15: 2 | AT15: Rue mnadzi moja quartier baitil mali | AU15: 97600 | AV15: Mamoudzou | AW15: Pas de voiture
A16: 321 | B16: 71 | C16: CADEMA 1 | D16: AO | E16: NON | F16: - | G16: - | H16: 15 | I16: C8 | J16: C5 | K16: RENE | L16: Assanati | M16: 0639 07 82 51 | O16: 024 065 633 000 18 | P16: NORD | Q16: 976-N-032 | R16: 1337 | S16: 45235 | T16: GR-921-XZ | U16: 45219 | V16: =2024-YEAR(U16) -> 1 | W16: 9 PLACES | Z16: OUI | AB16: NON | AD16: OUI | AE16: 48068 | AF16: F | AG16: _ | AH16: OUI | AI16: 2023 | AJ16: OUI | AK16: 2022 | AN16: 510 | AO16: 44171 | AP16: 150 | AS16: 32 | AT16: Rue bacar tsimanda | AU16: 97650 | AV16: Mtsangamouji
A17: 49 | B17: 20 | C17: CADEMA 1 | E17: NON | F17: NON | G17: NON | H17: 16 | J17: C9 | K17: SANDI | L17: Maanrouf | M17: 0639 40 58 85 | N17: maanroufsandi@laposte.net | O17: 024 069 635 000 19 | P17: Sud | Q17: 976-S-006 | R17: 1184 | S17: 45262 | T17: GW-255-NY | U17: 45406 | W17: 9 PLACES | X17: NEUF | Z17: NON | AA17: OUI | AB17: NON | AC17: NON | AD17: A VENIR | AE17: 46707 | AF17: F | AH17: OUI | AI17: OUI | AJ17: OUI | AK17: 2022 | AL17: NON | AN17: 510 | AO17: 43466 | AP17: 300 | AQ17: NON | AR17: NON | AT17: Quartier ecole primaire | AU17: 97620 | AV17: Chirongui | AW17: Pas habillé en attente rendez-vous mayotte equipement
A18: 177 | B18: 44 | C18: CADEMA 1 | E18: NON | F18: NON | G18: NON | H18: 17 | I18: C2 | J18: C11 | K18: TOUMBOU | L18: Toibourani | M18: 0639 19 14 22 | N18: toumboutoibourani@outlook.fr / anlia.toumbou97620@gmail.com | O18: 024 054 710 000 25 | P18: Mamoudzou | Q18: 976-M-177 | R18: 357 | S18: 45028 | T18: GF_215_AQ | U18: 44624 | V18: =2024-YEAR(U18) -> 2 | W18: 9 PLACES | X18: OK | Z18: 2023 | AA18: OUI | AB18: 2023 | AD18: OUI | AE18: 45992 | AF18: F | AH18: OUI | AI18: OUI | AJ18: NON | AK18: 2022 | AL18: OUI | AM18: 2020/158 | AN18: 510 | AO18: 43466 | AP18: 350 | AS18: 9 | AT18: Rue Bambou | AU18: 97620 | AV18: Chirongui | AW18: Gérant
A22: 17 | B22: 14 | C22: CADEMA 1 | E22: NON | F22: NON | G22: NON | H22: 2 | K22: ACHIRAFFI pas de chauffeur | L22: Assad | M22: 0639 29 01 58 | N22: achiraffis@gmail.com | O22: 024 046 617 000 15 | P22: Mamoudzou | Q22: 976-M-045 | R22: 90 | S22: 46916 | T22: FY-973-FL | U22: 44285 | V22: =2024-YEAR(U22) -> 3 | W22: 9 PLACES | X22: BON | Z22: OUI | AA22: OUI | AB22: OUI | AC22: OUI | AD22: NON | AE22: 49237 | AF22: F | AG22: _ | AH22: OUI | AI22: OUI | AJ22: OUI | AK22: 2022 | AL22: OUI | AM22: 2020/20 | AN22: 510 | AO22: 43466 | AP22: 450 | AQ22: NON | AR22: NON | AS22: 474 | AT22: Route départemental | AU22: 97630 | AV22: M'tsamboro | AW22: a une voiture - Travaille au Sud

Sheet Horaire détaillé
B2: , | C2: Planning de ramassage de PETITE-TERRE
B6: Ligne CHM PETITE-TERRE
B8: VEHICULES 8 PLACES | F8: MATIN
C10: SENS | F10: CHM-> Barge | G10: La Barge-> CHM | H10: CHM-> Barge | I10: CHM-> Barge | J10: La Barge-> CHM+CRA DIRECT | K10: CHM->Barge Direct | L10: La Barge-> CHM+CRA DIRECT | M10: La Barge-> CHM DIRECT | N10: CHM->Barge Direct | O10: La Barge-> CHM DIRECT
B11: Village | C11: Lieu de ramassage | D11: Non Direct | E11: Direct | F11: Heures de ramassage matin 5h40 CHM vers Barge | G11: Heures de ramassage matin 5:45 La Barge vers CHM | H11: Heures de ramassage matin 6h00 CHM vers Barge | I11: Heures de ramassage matin 6h30 CHM vers la barge | J11: Heures de ramassage matin 07h30 chm vers barge | K11: Heures de ramassage matin 06h55 barge vers chm | L11: Heures de ramassage matin 07h05 chm vers barge | M11: Heures de ramassage matin 07h30 barge vers CHM | N11: Heures de ramassage matin 07h50 CHM vers Barge | O11: Heures de ramassage matin 07h30 barge vers CHM
C12: CHAUFFEURS | F12: ='Feuille saisie'!C8 -> H1 | G12: =Horaire!H9 -> H5 | H12: ='Feuille saisie'!C10 -> H3 | I12: ='Feuille saisie'!C11 -> H1 | J12: ='Feuille saisie'!C12&"ET"&'Feuille saisie'!C13 -> H3ETH5 | K12: ='Feuille saisie'!C14&"ET"&'Feuille saisie'!C15 -> H1ETH5 | L12: ='Feuille saisie'!C16 -> H3 | M12: ='Feuille saisie'!C17 -> H5 | N12: ='Feuille saisie'!C18&" " -> H5 | O12: ='Feuille saisie'!C19 -> H1
B13: PAMANDZI | C13: CRA | D13: 0.0013888889 | E13: 0.0013888889 | J13: =J14+D13 -> 0.28125 | L13: =L14+D13 -> 0.30555556
B14: PAMANDZI | C14: CHM Marcel Henry | F14: ='Feuille saisie'!B8 -> 0.23263889 | G14: 0.25694444 | H14: ='Feuille saisie'!B10 -> 0.25 | I14: ='Feuille saisie'!B11 -> 0.27083333 | J14: =J28+$E$29 -> 0.27986111 | K14: ='Feuille saisie'!B14 -> 0.28819444 | L14: =L28+$E$29 -> 0.30416667 | M14: =M28+$E$29 -> 0.32152778 | N14: ='Feuille saisie'!B18 -> 0.32638889 | O14: =O28+$E$29 -> 0.33541667
B15: PAMANDZI | C15: =UPPER("la poste agence communale") -> LA POSTE AGENCE COMMUNALE | D15: 0.00069444444 | E15: 0.00069444444 | F15: =F14+D15 -> 0.23333333 | G15: =G16+D16 -> 0.25625 | H15: =H14+D15 -> 0.25069444 | I15: =I14+D15 -> 0.27152778
B16: PAMANDZI | C16: CIMETIERE PAMANDZI | D16: 0.00069444444 | E16: 0.00069444444 | F16: =D16+F15 -> 0.23402778 | G16: =G17+D17 -> 0.25555556 | H16: =H15+D16 -> 0.25138889 | I16: =I15+D16 -> 0.27222222
B17: PAMANDZI | C17: LYCEE DE PAMANDZI | D17: 0.0013888889 | E17: 0.00069444444 | F17: =D17+F16 -> 0.23541667 | G17: =G18+D18 -> 0.25416667 | H17: =H16+D17 -> 0.25277778 | I17: =I16+D17 -> 0.27361111
B18: PAMANDZI | C18: COLLEGE ZENA M'DERE PAMANDZI | D18: 0.0013888889 | E18: 0.00069444444 | F18: =D18+F17 -> 0.23680556 | G18: =G19+D19 -> 0.25277778 | H18: =H17+D18 -> 0.25416667 | I18: =I17+D18 -> 0.275
B19: PAMANDZI | C19: TUNNEL | D19: 0.0013888889 | E19: 0.00069444444 | F19: =D19+F18 -> 0.23819444 | G19: =G20+D20 -> 0.25138889 | H19: =H18+D19 -> 0.25555556 | I19: =I18+D19 -> 0.27638889
B20: LABATTOIR | C20: MADININA | D20: 0.0013888889 | E20: 0.00069444444 | F20: =D20+F19 -> 0.23958333 | G20: =G21+D21 -> 0.25 | H20: =H19+D20 -> 0.25694444 | I20: =I19+D20 -> 0.27777778
B21: LABATTOIR | C21: EN FACE DU RESTAURANT LE MOYA | D21: 0.0013888889 | E21: 0.00069444444 | F21: =D21+F20 -> 0.24097222 | G21: =G22+D22 -> 0.24861111 | H21: =H20+D21 -> 0.25833333 | I21: =I20+D21 -> 0.27916667
B22: LABATTOIR | C22: RELAI DE DZIANI | D22: 0.0013888889 | E22: 0.00069444444 | F22: =D22+F21 -> 0.24236111 | G22: =G23+D23 -> 0.24722222 | H22: =H21+D22 -> 0.25972222 | I22: =I21+D22 -> 0.28055556
B23: LABATTOIR | C23: EN FACE DE MAIMOUN DEPOT | D23: 0.00069444444 | E23: 0.00069444444 | F23: =D23+F22 -> 0.24305556 | G23: =G24+D24 -> 0.24652778 | H23: =H22+D23 -> 0.26041667 | I23: =I22+D23 -> 0.28125
B24: LABATTOIR | C24: CARREFOUR MARKET | D24: 0.0013888889 | E24: 0.00069444444 | F24: =D24+F23 -> 0.24444444 | G24: =G25+D25 -> 0.24513889 | H24: =H23+D24 -> 0.26180556 | I24: =I23+D24 -> 0.28263889
B25: LABATTOIR | C25: CIMETIERE LABATTOIR | D25: 0.0013888889 | E25: 0.00069444444 | F25: =D25+F24 -> 0.24583333 | G25: =G26+D26 -> 0.24375 | H25: =H24+D25 -> 0.26319444 | I25: =I24+D25 -> 0.28402778
B26: LABATTOIR | C26: =UPPER("acrinternation allineart tattoo") -> ACRINTERNATION ALLINEART TATTOO | D26: 0.0013888889 | E26: 0 | F26: =D26+F25 -> 0.24722222 | G26: =G27+D27 -> 0.24236111 | H26: =H25+D26 -> 0.26458333 | I26: =I25+D26 -> 0.28541667
B27: LABATTOIR | C27: SOMACO LABATTOIR | D27: 0.0013888889 | E27: 0.00069444444 | F27: =D27+F26 -> 0.24861111 | G27: =G28+D28 -> 0.24097222 | H27: =H26+D27 -> 0.26597222 | I27: =I26+D27 -> 0.28680556
B28: DZAOUDZI | C28: BARGE DE DZAOUDZI | D28: 0.0013888889 | E28: 0.00069444444 | F28: =D28+F27 -> 0.25 | G28: 0.23958333 | H28: =H27+D28 -> 0.26736111 | I28: =I27+D28 -> 0.28819444 | J28: ='Feuille saisie'!B12 -> 0.27083333 | K28: =K14+$E$29 -> 0.29722222 | L28: ='Feuille saisie'!B16 -> 0.29513889 | M28: ='Feuille saisie'!B17 -> 0.3125 | N28: =N14+E29 -> 0.33541667 | O28: ='Feuille saisie'!B19 -> 0.32638889
D29: =SUM(D15:D28) -> 0.017361111 | E29: =SUM(E15:E28) -> 0.0090277778 | G29: NEW
B34: Ligne CHM PETITE-TERRE
B36: VEHICULES 8 PLACES | F36: APRES-MIDI ET SOIREE
C38: SENS | F38: CHM-> Barge Direct | G38: La Barge-> CHM | H38: La Barge-> CHM | I38: CHM-> Barge Direct | J38: La Barge-> CHM | K38: La Barge-> CHM | L38: La Barge-> CHM | M38: La Barge-> CHM | N38: La Barge-> CHM Direct | O38: CHM-> Barge Direct | P38: La Barge-> CHM Direct | Q38: CHM-> Barge Direct | R38: La Barge-> CHM Direct | S38: CRA+CHM-> Barge Direct | T38: La Barge-> CHM Direct
B39: Village | C39: Lieu de ramassage | D39: Non Direct | E39: Direct | F39: Heures de ramassage 14:00 | G39: Heures de ramassage après midi 14h00 barge vers le CHM | H39: Heure de rammasage à 14:45 vers le CHM | I39: Heures de ramassage après midi 15h00 pharmacie vers la barge | J39: Heures de ramassage après midi 15h20 La barge vers le CHM | K39: Heures de ramassage après midi 15h50 La barge vers le CHM | L39: Heures de ramassage après midi 16h30 La barge vers le CHM | M39: Heures de ramassage après midi 17h00 La barge vers le CHM | N39: Heures de ramassage après midi 18h15 La barge vers le CHM | O39: Heures de ramassage après midi 18h15 barge vers chm | P39: Heures de ramassage après midi 18h15 La barge vers le CHM | Q39: Heures de ramassage après midi 18h45 chm vers barge | R39: Heures de ramassage après midi 18h15 La barge vers le CHM | S39: Heures de ramassage après midi 19h25 chm vers la barge | T39: Heures de ramassage après midi 19h45 La Barge vers CHM
C40: CHAUFFEURS | F40: ='Feuille saisie'!C25 -> H3 | G40: ='Feuille saisie'!C24 -> H1 | H40: ='Feuille saisie'!C26&"ET"&'Feuille saisie'!C27 -> H1ETH3 | I40: ='Feuille saisie'!C28 -> H5 | J40: ='Feuille saisie'!C29 -> H1 | K40: ='Feuille saisie'!C30 -> H5 | L40: ='Feuille saisie'!C31 -> H5 | M40: ='Feuille saisie'!C32 -> H5 | N40: ='Feuille saisie'!C33 -> H3 | O40: ='Feuille saisie'!C34 -> H1 | P40: =Horaire!H31 -> H1 | Q40: =Horaire!H32 -> H3 | R40: =Horaire!H33 -> H3 | S40: ='Feuille saisie'!C29 -> H1 | T40: =Horaire!H35 -> H3
B41: PAMANDZI | C41: CRA | E41: 0.0013888889 | S41: 0.80902778 | T41: ='Feuille saisie'!C36 -> H3
B42: PAMANDZI | C42: CHM Marcel Henry | D42: 0.0013888889 | F42: ='Feuille saisie'!B24 -> 0.58333333 | G42: =G43+D43 -> 0.60069444 | H42: =H43+D43 -> 0.63194444 | I42: ='Feuille saisie'!B28 -> 0.625 | J42: =J43+D43 -> 0.65625 | K42: =K43+D43 -> 0.67708333 | L42: =L43+D43 -> 0.70486111 | M42: =M43+D43 -> 0.72916667 | N42: =N56+$E$57 -> 0.76944444 | O42: ='Feuille saisie'!B33 -> 0.76041667 | P42: =P43+D43 -> 0.79861111 | Q42: ='Feuille saisie'!B35 -> 0.78125 | R42: =R43+D43 -> 0.81944444 | S42: =S41+D42 -> 0.81041667 | T42: =T43+D43 -> 0.84027778
B43: PAMANDZI | C43: =UPPER("la poste agence communale") -> LA POSTE AGENCE COMMUNALE | D43: =D15 -> 0.00069444444 | E43: =E15 -> 0.00069444444 | G43: =G44+D44 -> 0.6 | H43: =H44+D44 -> 0.63125 | J43: =J44+D44 -> 0.65555556 | K43: =K44+D44 -> 0.67638889 | L43: =L44+D44 -> 0.70416667 | M43: =M44+D44 -> 0.72847222 | P43: =P44+D44 -> 0.79791667 | R43: =R44+D44 -> 0.81875 | T43: =T44+D44 -> 0.83958333
B44: PAMANDZI | C44: CIMETIERE PAMANDZI | D44: =D16 -> 0.00069444444 | E44: =E16 -> 0.00069444444 | G44: =G45+D45 -> 0.59930556 | H44: =H45+D45 -> 0.63055556 | J44: =J45+D45 -> 0.65486111 | K44: =K45+D45 -> 0.67569444 | L44: =L45+D45 -> 0.70347222 | M44: =M45+D45 -> 0.72777778 | P44: =P45+D45 -> 0.79722222 | R44: =R45+D45 -> 0.81805556 | T44: =T45+D45 -> 0.83888889
B45: PAMANDZI | C45: LYCEE DE PAMANDZI | D45: =D17 -> 0.0013888889 | E45: =E17 -> 0.00069444444 | G45: =G46+D46 -> 0.59791667 | H45: =H46+D46 -> 0.62916667 | J45: =J46+D46 -> 0.65347222 | K45: =K46+D46 -> 0.67430556 | L45: =L46+D46 -> 0.70208333 | M45: =M46+D46 -> 0.72638889 | P45: =P46+D46 -> 0.79583333 | R45: =R46+D46 -> 0.81666667 | T45: =T46+D46 -> 0.8375
B46: PAMANDZI | C46: COLLEGE ZENA M'DERE PAMANDZI | D46: =D18 -> 0.0013888889 | E46: =E18 -> 0.00069444444 | G46: =G47+D47 -> 0.59652778 | H46: =H47+D47 -> 0.62777778 | J46: =J47+D47 -> 0.65208333 | K46: =K47+D47 -> 0.67291667 | L46: =L47+D47 -> 0.70069444 | M46: =M47+D47 -> 0.725 | P46: =P47+D47 -> 0.79444444 | R46: =R47+D47 -> 0.81527778 | T46: =T47+D47 -> 0.83611111
B47: PAMANDZI | C47: TUNNEL | D47: =D19 -> 0.0013888889 | E47: =E19 -> 0.00069444444 | G47: =G48+D48 -> 0.59513889 | H47: =H48+D48 -> 0.62638889 | J47: =J48+D48 -> 0.65069444 | K47: =K48+D48 -> 0.67152778 | L47: =L48+D48 -> 0.69930556 | M47: =M48+D48 -> 0.72361111 | P47: =P48+D48 -> 0.79305556 | R47: =R48+D48 -> 0.81388889 | T47: =T48+D48 -> 0.83472222
B48: LABATTOIR | C48: MADININA | D48: =D20 -> 0.0013888889 | E48: =E20 -> 0.00069444444 | G48: =G49+D49 -> 0.59375 | H48: =H49+D49 -> 0.625 | J48: =J49+D49 -> 0.64930556 | K48: =K49+D49 -> 0.67013889 | L48: =L49+D49 -> 0.69791667 | M48: =M49+D49 -> 0.72222222 | P48: =P49+D49 -> 0.79166667 | R48: =R49+D49 -> 0.8125 | T48: =T49+D49 -> 0.83333333
B49: LABATTOIR | C49: EN FACE DU RESTAURANT LE MOYA | D49: =D21 -> 0.0013888889 | E49: =E21 -> 0.00069444444 | G49: =G50+D50 -> 0.59236111 | H49: =H50+D50 -> 0.62361111 | J49: =J50+D50 -> 0.64791667 | K49: =K50+D50 -> 0.66875 | L49: =L50+D50 -> 0.69652778 | M49: =M50+D50 -> 0.72083333 | P49: =P50+D50 -> 0.79027778 | R49: =R50+D50 -> 0.81111111 | T49: =T50+D50 -> 0.83194444
B50: LABATTOIR | C50: RELAI DE DZIANI | D50: =D22 -> 0.0013888889 | E50: =E22 -> 0.00069444444 | G50: =G51+D51 -> 0.59097222 | H50: =H51+D51 -> 0.62222222 | J50: =J51+D51 -> 0.64652778 | K50: =K51+D51 -> 0.66736111 | L50: =L51+D51 -> 0.69513889 | M50: =M51+D51 -> 0.71944444 | P50: =P51+D51 -> 0.78888889 | R50: =R51+D51 -> 0.80972222 | T50: =T51+D51 -> 0.83055556
B51: LABATTOIR | C51: EN FACE DE MAIMOUN DEPOT | D51: =D23 -> 0.00069444444 | E51: =E23 -> 0.00069444444 | G51: =G52+D52 -> 0.59027778 | H51: =H52+D52 -> 0.62152778 | J51: =J52+D52 -> 0.64583333 | K51: =K52+D52 -> 0.66666667 | L51: =L52+D52 -> 0.69444444 | M51: =M52+D52 -> 0.71875 | P51: =P52+D52 -> 0.78819444 | R51: =R52+D52 -> 0.80902778 | T51: =T52+D52 -> 0.82986111
B52: LABATTOIR | C52: CARREFOUR MARKET | D52: =D24 -> 0.0013888889 | E52: =E24 -> 0.00069444444 | G52: =G53+D53 -> 0.58888889 | H52: =H53+D53 -> 0.62013889 | J52: =J53+D53 -> 0.64444444 | K52: =K53+D53 -> 0.66527778 | L52: =L53+D53 -> 0.69305556 | M52: =M53+D53 -> 0.71736111 | P52: =P53+D53 -> 0.78680556 | R52: =R53+D53 -> 0.80763889 | T52: =T53+D53 -> 0.82847222
...

Sheet Feuil2
D2: MARCHE AGENT CHM PETITE TERRE
D3: PLANNING INITIAL
G5: CHAUFFEURS
B6: HEURE DE DEPART | C6: LIEU DE DEPART ET DESTINATION | D6: DIRECT | E6: H1 | F6: H2 | G6: H3 | H6: H4 | I6: H5 | J6: H6
E7: Lundi au Samedi | G7: Dimanche | H7: Lundi au Vendredi | J7: Dimanche
B9: 0.23958333 | C9: CHM-> BARGE | D9: NON | E9: X | F9: X | G9: X
B10: 0.26041667 | C10: BARGE-> CHM | D10: OUI | E10: X | F10: X | G10: X | I10: EN RESERVE
B11: 0.28125 | C11: CHM-> BARGE | D11: NON | E11: X | F11: X | G11: X | I11: OPERATIONNEL MOIS
B12: 0.30208333 | C12: BARGE-> CHM | D12: OUI | E12: X | F12: X | G12: X | I12: SUIVANT
B13: 0.3125 | C13: CHM-> BARGE | D13: NON | E13: X | F13: X | G13: X
B15: 0.58333333 | C15: CHM->BARGE | D15: OUI | E15: X | F15: X | G15: X
B16: 0.625 | C16: CHM->BARGE | D16: OUI | E16: X | G16: X
B17: 0.76041667 | C17: CHM->BARGE | D17: NON | E17: X | G17: X
B18: 0.78125 | C18: CHM->BARGE | D18: NON | F18: X | G18: X
B19: 0.8125 | C19: CHM->BARGE | D19: NON | F19: X | G19: X
C21: Nbre trajets | E21: 8 | F21: 8 | G21: 10
E22: 3h/jrs | F22: 3h/jrs | G22: 4h/jrs
C23: Montant par mois | E23: >1920€ | F23: >1920€ | G23: >1040€
C24: Prix au trajet supplémentaire | E24: 12 | F24: 12 | G24: 14€ le dimanche | H24: 12 | I24: 12 | J24: 14€ le dimanche
D26: RESPECT DES HORAIRES
D27: VEHICULE PROPRE ET CLIMATISE
D28: QUALITE D'ACCUEIL
D29: ESPRIT D'EQUIPE
D30: COORDINATEUR : IBRAHIM HAMADA
D31: AFFICHETTES MAGNETIQUES INDIQUANT NAVETTE CHM
D32: CONTRÔLE DES BADGES CHM
D33: DATE DE DEPART : 1/02/2026 (DIMANCHE)

Sheet Previsions facturation
B4: Mois | C4: 46054
C6: Type de trajets | F6: Nombre de trajet quotidien | G6: Nombre de véhicules | H6: Nombre de jours dans le mois | I6: Tarif | J6: Valeur | K6: Tarif achat | L6: Cout achat | N6: Chauffeur | O6: Nbre trajets quotidiens | P6: Nbre jour | Q6: Tarif | R6: Valeur
B7: Jours de la semaine hors samedi, dimanche et jours fériés | C7: Trajets véhicules 8 places avant 7:00 | F7: 3 | G7: 2 | H7: =28-H12-H17 -> 20 | I7: 15.85 | J7: =F7*H7*I7*G7 -> 1902 | K7: 12 | L7: =F7*H7*K7*G7 -> 1440 | N7: H1
C8: Trajets véhicules 8 places de 7:00 à 7:30 | F8: 2 | G8: 2 | I8: 15.06 | J8: =F8*H$7*I8*G8 -> 1204.8 | K8: 12 | L8: =F8*H$7*K8*G8 -> 960 | N8: Semaine 1 et 2 | O8: 8 | P8: 12 | Q8: =K7 -> 12 | R8: =O8*P8*Q8 -> 1152
C9: Trajets véhicules 8 places de 14:00 | F9: 1 | G9: 2 | I9: 15.06 | J9: =F9*H$7*I9*G9 -> 602.4 | K9: 12 | L9: =F9*H$7*K9*G9 -> 480 | N9: Semaine 3 et 4 | O9: 8 | P9: 12 | Q9: =K7 -> 12 | R9: =O9*P9*Q9 -> 1152
C10: Trajets véhicules 8 places de 15:00 à 19:30 | F10: 4 | G10: 1 | I10: 15.06 | J10: =F10*H$7*I10*G10 -> 1204.8 | K10: 12 | L10: =F10*H$7*K10*G10 -> 960 | R10: =SUM(R8:R9) -> 2304
F11: =F7*G7+F8*G8+F9*G9+F10*G10 -> 16 | H11: =F11*H7 -> 320 | I11: Trajets | N11: H2
B12: Samedis | C12: Trajets véhicules 8 places avant 7:00 | F12: 3 | G12: 2 | H12: 4 | I12: 15.85 | J12: =F12*H$12*I12*G12 -> 380.4 | K12: 12 | L12: =F12*H$12*K12*G12 -> 288 | N12: Semaine 1 et 2 | O12: 8 | P12: 12 | Q12: =K8 -> 12 | R12: =O12*P12*Q12 -> 1152
C13: Trajets véhicules 8 places de 7:00 à 7:30 | F13: 2 | G13: 2 | I13: 15.06 | J13: =F13*H$12*I13*G13 -> 240.96 | K13: 12 | L13: =F13*H$12*K13*G13 -> 192 | N13: Semaine 3 et 4 | O13: 8 | P13: 12 | Q13: =K7 -> 12 | R13: =O13*P13*Q13 -> 1152
C14: Trajets véhicules 8 places de 14:00 | F14: 1 | G14: 2 | I14: 15.06 | J14: =F14*H$12*I14*G14 -> 120.48 | K14: 12 | L14: =F14*H$12*K14*G14 -> 96 | R14: =SUM(R11:R13) -> 2304
C15: Trajets véhicules 8 places de 15:00 à 19:30 | F15: 4 | G15: 1 | I15: 15.06 | J15: =F15*H$12*I15*G15 -> 240.96 | K15: 12 | L15: =F15*H$12*K15*G15 -> 192 | N15: H3
F16: =F12*G12+F13*G13+F14*G14+F15*G15 -> 16 | H16: =F16*H12 -> 64 | I16: Trajets
B17: Dimanches et jours fériés | C17: Trajets véhicules 8 places avant 7:00 | F17: 3 | G17: 1 | H17: 4 | I17: 17.39 | J17: =F17*H$17*I17*G17 -> 208.68 | K17: 14 | L17: =F17*H$17*K17*G17 -> 168 | N17: Dimanche | O17: 10 | P17: 4 | Q17: =K17 -> 14 | R17: =O17*P17*Q17 -> 560
C18: Trajets véhicules 8 places de 7:00 à 7:30 | F18: 2 | G18: 1 | I18: 16.61 | J18: =F18*H$17*I18*G18 -> 132.88 | K18: 14 | L18: =F18*H$17*K18*G18 -> 112 | R18: =SUM(R16:R17) -> 560
C19: Trajets véhicules 8 places de 14:00 | F19: 1 | G19: 1 | I19: 16.61 | J19: =F19*H$17*I19*G19 -> 66.44 | K19: 14 | L19: =F19*H$17*K19*G19 -> 56 | R19: =R10+R14+R18 -> 5168
C20: Trajets véhicules 8 places de 15:00 à 19:30 | F20: 4 | G20: 1 | I20: =I19 -> 16.61 | J20: =F20*H$17*I20*G20 -> 265.76 | K20: 14 | L20: =F20*H$17*K20*G20 -> 224
F21: =F17*G17+F18*G18+F19*G19+F20*G20 -> 10 | H21: =F21*H17 -> 40 | I21: Trajets
C22: TOTAL MOIS | H22: =H11+H16+H21 -> 424 | I22: Trajets | J22: =SUM(J7:J21) -> 6570.56 | L22: =SUM(L7:L21) -> 5168
K24: Marge direct | L24: =J22-L22 -> 1402.56 | M24: =L24/J22 -> 0.21346126
K25: Coordinateur | L25: =500*1 -> 500
K26: Marge | L26: =L24-L25 -> 902.56 | M26: =L26/J22 -> 0.13736424

Sheet Feuille saisie dimanché
G1: ù
A2: TYPE | B2: H5
A3: DATE | B3: 45627
A4: CHAUFFEUR | B4: =VLOOKUP(B2,'Liste chauffeur'!$B$5:$L$19,2,TRUE)&" "&VLOOKUP(B2,'Liste chauffeur'!$B$5:$L$19,3,TRUE) -> ATTOUMANI Kamaldine
J6: Arrêt 1 | M6: ARRIVEE | Q6: 8
A7: LIEU DE DEPART | B7: Heure théorique départ | C7: Horaire | D7: Chauffeur | E7: Direct/Non Direct | F7: Heure réelle départ | G7: Trajet non effectué | H7: Départ avec plus de 10 mns retard | I7: Nbre personnes montée | J7: - | K7: + | L7: Nbre personnes descente | M7: Heure arrivée finale | N7: Commentaires | O7: Temps Aller | P7: Nbre personnes moyenne | Q7: Capacité max | R7: Taux Fréquentation
A8: ='Horaire dimanche2'!A8 -> CHM | B8: ='Horaire dimanche2'!E8 -> 0.23263889 | C8: ='Horaire dimanche2'!H8 -> H1 | D8: =VLOOKUP(C8,'Liste chauffeur'!$B$5:$L$19,2,TRUE)&" "&VLOOKUP(C8,'Liste chauffeur'!$B$5:$L$19,3,TRUE) -> CHADHOULI Houmadi | E8: ='Horaire dimanche2'!C8 -> 13 ARRETS | G8: =COUNTBLANK(F8) -> 1 | O8: =IF(G8=1,"",M8-F8) | P8: =I8+K8-J8 -> 0 | Q8: =IF(G8=1,0,Q$6) -> 0 | R8: =IF(Q8=0,0,P8/Q8) -> 0
A9: ='Horaire dimanche2'!A9 -> CHM | B9: ='Horaire dimanche2'!E9 -> 0.25 | C9: ='Horaire dimanche2'!H9 -> H3 | D9: =VLOOKUP(C9,'Liste chauffeur'!$B$5:$L$19,2,TRUE)&" "&VLOOKUP(C9,'Liste chauffeur'!$B$5:$L$19,3,TRUE) -> SAID ALI Kamile | E9: ='Horaire dimanche2'!C9 -> 13 ARRETS | G9: =COUNTBLANK(F9) -> 1 | O9: =IF(G9=1,"",M9-F9) | P9: =I9+K9-J9 -> 0 | Q9: =IF(G9=1,0,Q$6) -> 0 | R9: =IF(Q9=0,0,P9/Q9) -> 0
A10: ='Horaire dimanche2'!A10 -> CHM | B10: ='Horaire dimanche2'!E10 -> 0.27083333 | C10: ='Horaire dimanche2'!H10 -> H1 | D10: =VLOOKUP(C10,'Liste chauffeur'!$B$5:$L$19,2,TRUE)&" "&VLOOKUP(C10,'Liste chauffeur'!$B$5:$L$19,3,TRUE) -> CHADHOULI Houmadi | E10: ='Horaire dimanche2'!C10 -> 13 ARRETS | G10: =COUNTBLANK(F10) -> 1 | O10: =IF(G10=1,"",M10-F10) | P10: =I10+K10-J10 -> 0 | Q10: =IF(G10=1,0,Q$6) -> 0 | R10: =IF(Q10=0,0,P10/Q10) -> 0
A11: ='Horaire dimanche2'!A11 -> LA BARGE | B11: ='Horaire dimanche2'!E11 -> 0.27083333 | C11: ='Horaire dimanche2'!H11 -> H3 | D11: =VLOOKUP(C11,'Liste chauffeur'!$B$5:$L$19,2,TRUE)&" "&VLOOKUP(C11,'Liste chauffeur'!$B$5:$L$19,3,TRUE) -> SAID ALI Kamile | E11: ='Horaire dimanche2'!C11 -> DIRECT | G11: =COUNTBLANK(F11) -> 1 | O11: =IF(G11=1,"",M11-F11) | P11: =I11+K11-J11 -> 0 | Q11: =IF(G11=1,0,Q$6) -> 0 | R11: =IF(Q11=0,0,P11/Q11) -> 0
A12: ='Horaire dimanche2'!A12 -> CHM | B12: ='Horaire dimanche2'!E12 -> 0.28819444 | C12: ='Horaire dimanche2'!H12 -> H1 | D12: =VLOOKUP(C12,'Liste chauffeur'!$B$5:$L$19,2,TRUE)&" "&VLOOKUP(C12,'Liste chauffeur'!$B$5:$L$19,3,TRUE) -> CHADHOULI Houmadi | E12: ='Horaire dimanche2'!C12 -> DIRECT | G12: =COUNTBLANK(F12) -> 1 | O12: =IF(G12=1,"",M12-F12) | P12: =I12+K12-J12 -> 0 | Q12: =IF(G12=1,0,Q$6) -> 0 | R12: =IF(Q12=0,0,P12/Q12) -> 0
A13: ='Horaire dimanche2'!A13 -> LA BARGE | B13: ='Horaire dimanche2'!E13 -> 0.29513889 | C13: ='Horaire dimanche2'!H13 -> H3 | D13: =VLOOKUP(C13,'Liste chauffeur'!$B$5:$L$19,2,TRUE)&" "&VLOOKUP(C13,'Liste chauffeur'!$B$5:$L$19,3,TRUE) -> SAID ALI Kamile | E13: ='Horaire dimanche2'!C13 -> DIRECT | G13: =COUNTBLANK(F13) -> 1 | O13: =IF(G13=1,"",M13-F13) | P13: =I13+K13-J13 -> 0 | Q13: =IF(G13=1,0,Q$6) -> 0 | R13: =IF(Q13=0,0,P13/Q13) -> 0
A14: ='Horaire dimanche2'!A14 -> LA BARGE | B14: ='Horaire dimanche2'!E14 -> 0.3125 | C14: ='Horaire dimanche2'!H14 -> H5 | D14: =VLOOKUP(C14,'Liste chauffeur'!$B$5:$L$19,2,TRUE)&" "&VLOOKUP(C14,'Liste chauffeur'!$B$5:$L$19,3,TRUE) -> ATTOUMANI Kamaldine | E14: ='Horaire dimanche2'!C14 -> DIRECT | G14: =COUNTBLANK(F14) -> 1 | O14: =IF(G14=1,"",M14-F14) | P14: =I14+K14-J14 -> 0 | Q14: =IF(G14=1,0,Q$6) -> 0 | R14: =IF(Q14=0,0,P14/Q14) -> 0
A15: ='Horaire dimanche2'!A15 -> LA BARGE | B15: ='Horaire dimanche2'!E15 -> 0.32638889 | C15: ='Horaire dimanche2'!H15 -> H5 | D15: =VLOOKUP(C15,'Liste chauffeur'!$B$5:$L$19,2,TRUE)&" "&VLOOKUP(C15,'Liste chauffeur'!$B$5:$L$19,3,TRUE) -> ATTOUMANI Kamaldine | E15: ='Horaire dimanche2'!C15 -> DIRECT | G15: =COUNTBLANK(F15) -> 1 | O15: =IF(G15=1,"",M15-F15) | P15: =I15+K15-J15 -> 0 | Q15: =IF(G15=1,0,Q$6) -> 0 | R15: =IF(Q15=0,0,P15/Q15) -> 0
B16: NON PLANIFIE | G16: =COUNTBLANK(F16) -> 1 | O16: =IF(G16=1,"",M16-F16) | P16: =I16+K16-J16 -> 0 | Q16: =IF(G16=1,0,Q$6) -> 0 | R16: =IF(Q16=0,0,P16/Q16) -> 0
B17: NON PLANIFIE | G17: =COUNTBLANK(F17) -> 1 | P17: =I17+K17-J17 -> 0 | Q17: =IF(G17=1,0,Q$6) -> 0 | R17: =IF(Q17=0,0,P17/Q17) -> 0
A18: ='Horaire dimanche'!A18 -> 0 | B18: ='Horaire dimanche'!E18 -> 0 | C18: ='Horaire dimanche'!H18 -> 0 | D18: =VLOOKUP(C18,'Liste chauffeur'!$B$5:$L$19,2,TRUE)&" "&VLOOKUP(C18,'Liste chauffeur'!$B$5:$L$19,3,TRUE) -> #N/A | E18: ='Horaire dimanche'!C18 -> 0 | G18: =SUM(G8:G17) -> 10 | H18: =SUM(H8:H17) -> 0 | O18: =AVERAGE(O8:O17) -> #DIV/0! | P18: =SUM(P8:P17) -> 0 | Q18: =SUM(Q8:Q17) -> 0 | R18: =P18/Q18 -> #DIV/0!
A19: ='Horaire dimanche2'!A16 -> LA BARGE | B19: ='Horaire dimanche2'!E16 -> 0.58333333 | C19: ='Horaire dimanche2'!H16 -> H1 | D19: =VLOOKUP(C19,'Liste chauffeur'!$B$5:$L$19,2,TRUE)&" "&VLOOKUP(C19,'Liste chauffeur'!$B$5:$L$19,3,TRUE) -> CHADHOULI Houmadi | E19: ='Horaire dimanche2'!C16 -> 13 ARRETS | G19: =COUNTBLANK(F19) -> 1 | O19: =IF(G19=1,"",M19-F19) | P19: =I19+K19-J19 -> 0 | Q19: =IF(G19=1,0,Q$6) -> 0 | R19: =IF(Q19=0,0,P19/Q19) -> 0
A20: ='Horaire dimanche2'!A17 -> CHM | B20: ='Horaire dimanche2'!E17 -> 0.58333333 | C20: ='Horaire dimanche2'!H17 -> H3 | D20: =VLOOKUP(C20,'Liste chauffeur'!$B$5:$L$19,2,TRUE)&" "&VLOOKUP(C20,'Liste chauffeur'!$B$5:$L$19,3,TRUE) -> SAID ALI Kamile | E20: ='Horaire dimanche2'!C17 -> DIRECT | G20: =COUNTBLANK(F20) -> 1 | O20: =IF(G20=1,"",M20-F20) | P20: =I20+K20-J20 -> 0 | Q20: =IF(G20=1,0,Q$6) -> 0 | R20: =IF(Q20=0,0,P20/Q20) -> 0
A21: ='Horaire dimanche2'!A18 -> LA BARGE | B21: ='Horaire dimanche2'!E18 -> 0.61458333 | C21: ='Horaire dimanche2'!H18 -> H1 | D21: =VLOOKUP(C21,'Liste chauffeur'!$B$5:$L$19,2,TRUE)&" "&VLOOKUP(C21,'Liste chauffeur'!$B$5:$L$19,3,TRUE) -> CHADHOULI Houmadi | E21: ='Horaire dimanche2'!C18 -> 13 ARRETS | G21: =COUNTBLANK(F21) -> 1 | O21: =IF(G21=1,"",M21-F21) | P21: =I21+K21-J21 -> 0 | Q21: =IF(G21=1,0,Q$6) -> 0 | R21: =IF(Q21=0,0,P21/Q21) -> 0
A22: ='Horaire dimanche2'!A19 -> CHM | B22: ='Horaire dimanche2'!E19 -> 0.625 | C22: ='Horaire dimanche2'!H19 -> H3 | D22: =VLOOKUP(C22,'Liste chauffeur'!$B$5:$L$19,2,TRUE)&" "&VLOOKUP(C22,'Liste chauffeur'!$B$5:$L$19,3,TRUE) -> SAID ALI Kamile | E22: ='Horaire dimanche2'!C19 -> DIRECT | G22: =COUNTBLANK(F22) -> 1 | O22: =IF(G22=1,"",M22-F22) | P22: =I22+K22-J22 -> 0 | Q22: =IF(G22=1,0,Q$6) -> 0 | R22: =IF(Q22=0,0,P22/Q22) -> 0
A23: ='Horaire dimanche2'!A20 -> LA BARGE | B23: ='Horaire dimanche2'!E20 -> 0.63888889 | C23: ='Horaire dimanche2'!H20 -> H1 | D23: =VLOOKUP(C23,'Liste chauffeur'!$B$5:$L$19,2,TRUE)&" "&VLOOKUP(C23,'Liste chauffeur'!$B$5:$L$19,3,TRUE) -> CHADHOULI Houmadi | E23: ='Horaire dimanche2'!C20 -> 13 ARRETS | G23: =COUNTBLANK(F23) -> 1 | O23: =IF(G23=1,"",M23-F23) | P23: =I23+K23-J23 -> 0 | Q23: =IF(G23=1,0,Q$6) -> 0 | R23: =IF(Q23=0,0,P23/Q23) -> 0
A24: ='Horaire dimanche2'!A21 -> LA BARGE | B24: ='Horaire dimanche2'!E21 -> 0.65972222 | C24: ='Horaire dimanche2'!H21 -> H5 | D24: =VLOOKUP(C24,'Liste chauffeur'!$B$5:$L$19,2,TRUE)&" "&VLOOKUP(C24,'Liste chauffeur'!$B$5:$L$19,3,TRUE) -> ATTOUMANI Kamaldine | E24: ='Horaire dimanche2'!C21 -> 13 ARRETS | G24: =COUNTBLANK(F24) -> 1 | O24: =IF(G24=1,"",M24-F24) | P24: =I24+K24-J24 -> 0 | Q24: =IF(G24=1,0,Q$6) -> 0 | R24: =IF(Q24=0,0,P24/Q24) -> 0
A25: ='Horaire dimanche2'!A22 -> LA BARGE | B25: ='Horaire dimanche2'!E22 -> 0.6875 | C25: ='Horaire dimanche2'!H22 -> H5 | D25: =VLOOKUP(C25,'Liste chauffeur'!$B$5:$L$19,2,TRUE)&" "&VLOOKUP(C25,'Liste chauffeur'!$B$5:$L$19,3,TRUE) -> ATTOUMANI Kamaldine | E25: ='Horaire dimanche2'!C22 -> 13 ARRETS | G25: =COUNTBLANK(F25) -> 1 | O25: =IF(G25=1,"",M25-F25) | P25: =I25+K25-J25 -> 0 | Q25: =IF(G25=1,0,Q$6) -> 0 | R25: =IF(Q25=0,0,P25/Q25) -> 0
A26: ='Horaire dimanche2'!A23 -> CHM | B26: ='Horaire dimanche2'!E23 -> 0.76041667 | C26: ='Horaire dimanche2'!H23 -> H3 | D26: =VLOOKUP(C26,'Liste chauffeur'!$B$5:$L$19,2,TRUE)&" "&VLOOKUP(C26,'Liste chauffeur'!$B$5:$L$19,3,TRUE) -> SAID ALI Kamile | E26: ='Horaire dimanche2'!C23 -> DIRECT | G26: =COUNTBLANK(F26) -> 1 | O26: =IF(G26=1,"",M26-F26) | P26: =I26+K26-J26 -> 0 | Q26: =IF(G26=1,0,Q$6) -> 0 | R26: =IF(Q26=0,0,P26/Q26) -> 0
A27: ='Horaire dimanche2'!A24 -> LA BARGE | B27: ='Horaire dimanche2'!E24 -> 0.76041667 | C27: ='Horaire dimanche2'!H24 -> H5 | D27: =VLOOKUP(C27,'Liste chauffeur'!$B$5:$L$19,2,TRUE)&" "&VLOOKUP(C27,'Liste chauffeur'!$B$5:$L$19,3,TRUE) -> ATTOUMANI Kamaldine | E27: ='Horaire dimanche2'!C24 -> 13 ARRETS
A28: ='Horaire dimanche2'!A25 -> CHM | B28: ='Horaire dimanche2'!E25 -> 0.78125 | C28: ='Horaire dimanche2'!H25 -> H5 | D28: =VLOOKUP(C28,'Liste chauffeur'!$B$5:$L$19,2,TRUE)&" "&VLOOKUP(C28,'Liste chauffeur'!$B$5:$L$19,3,TRUE) -> ATTOUMANI Kamaldine | E28: ='Horaire dimanche2'!C25 -> DIRECT
A29: ='Horaire dimanche2'!A26 -> LA BARGE | B29: ='Horaire dimanche2'!E26 -> 0.78125 | C29: ='Horaire dimanche2'!H26 -> H3 | D29: =VLOOKUP(C29,'Liste chauffeur'!$B$5:$L$19,2,TRUE)&" "&VLOOKUP(C29,'Liste chauffeur'!$B$5:$L$19,3,TRUE) -> SAID ALI Kamile | E29: ='Horaire dimanche2'!C26 -> 13 ARRETS | G29: =COUNTBLANK(F29) -> 1
A30: ='Horaire dimanche2'!A27 -> CRA+CHM | B30: ='Horaire dimanche2'!E27 -> 0.80902778 | C30: ='Horaire dimanche2'!H27 -> H5 | D30: =VLOOKUP(C30,'Liste chauffeur'!$B$5:$L$19,2,TRUE)&" "&VLOOKUP(C30,'Liste chauffeur'!$B$5:$L$19,3,TRUE) -> ATTOUMANI Kamaldine | E30: ='Horaire dimanche2'!C27 -> DIRECT
A31: ='Horaire dimanche2'!A28 -> LA BARGE | B31: ='Horaire dimanche2'!E28 -> 0.82291667 | C31: ='Horaire dimanche2'!H28 -> H5 | D31: =VLOOKUP(C31,'Liste chauffeur'!$B$5:$L$19,2,TRUE)&" "&VLOOKUP(C31,'Liste chauffeur'!$B$5:$L$19,3,TRUE) -> ATTOUMANI Kamaldine | E31: ='Horaire dimanche2'!C28 -> 13 ARRETS
B32: NON PLANIFIE | G32: =COUNTBLANK(F32) -> 1 | O32: =IF(G32=1,"",M32-F32) | P32: =I32+K32-J32 -> 0 | Q32: =IF(G32=1,0,Q$6) -> 0 | R32: =IF(Q32=0,0,P32/Q32) -> 0
B33: NON PLANIFIE | G33: =COUNTBLANK(F33) -> 1 | P33: =I33+K33-J33 -> 0 | Q33: =IF(G33=1,0,Q$6) -> 0 | R33: =IF(Q33=0,0,P33/Q33) -> 0
B34: ST2 | C34: ST | G34: =SUM(#REF!) -> #REF! | O34: =AVERAGE(#REF!) -> #REF! | P34: =SUM(#REF!) -> #REF! | Q34: =SUM(#REF!) -> #REF! | R34: =IF(Q34=0,0,P34/Q34) -> #REF!
A35: REMPLACEMENT | C35: H | O35: =AVERAGE(O8:O17,#REF!) -> #REF! | P35: =P18+P34 -> #REF! | Q35: =Q18+Q34 -> #REF! | R35: =IF(Q35=0,0,P35/Q35) -> #REF!
A36: REMPLACEMENT | C36: H
A37: REMPLACEMENT | C37: H
A38: REMPLACEMENT | C38: H
A39: REMPLACEMENT | C39: H
C41: S | F41: Signature Chauffeur | J41: Signature Coordinateur
B44: Statistiques | C44: nbre de trajets planifiés | D44: Nbre trajets non effectués | F44: Nbre trajets effectués non planifiés
...

Sheet Feuille saisie
G1: ù
A2: TYPE | B2: H1
A3: DATE | B3: 45627
A4: CHAUFFEUR | B4: =VLOOKUP(B2,'Liste chauffeur'!$B$5:$L$19,2,TRUE)&" "&VLOOKUP(B2,'Liste chauffeur'!$B$5:$L$19,3,TRUE) -> CHADHOULI Houmadi
K6: ARRIVEE | O6: 8
A7: LIEU DE DEPART | B7: Heure théorique départ | C7: Horaire | D7: Chauffeur | E7: Direct/Non Direct | F7: Heure réelle départ | G7: Trajet non effectué | H7: Départ avec plus de 10 mns retard | I7: Nbre personnes montée | J7: Nbre personnes descente | K7: Heure arrivée finale | L7: Commentaires | M7: Temps Aller | N7: Nbre personnes moyenne | O7: Capacité max | P7: Taux Fréquentation
A8: =Horaire!A8 -> CHM | B8: =Horaire!E8 -> 0.23263889 | C8: =Horaire!H8 -> H1 | D8: =VLOOKUP(C8,'Liste chauffeur'!$B$5:$L$19,2,TRUE)&" "&VLOOKUP(C8,'Liste chauffeur'!$B$5:$L$19,3,TRUE) -> CHADHOULI Houmadi | E8: =Horaire!C8 -> 13 ARRETS | G8: =COUNTBLANK(F8) -> 1 | M8: =IF(G8=1,"",K8-F8) | N8: =J8 -> 0 | O8: =IF(G8=1,0,O$6) -> 0 | P8: =IF(O8=0,0,N8/O8) -> 0
A9: =Horaire!A9 -> LA BARGE | B9: =Horaire!E9 -> 0.23958333 | C9: =Horaire!H9 -> H5 | D9: =VLOOKUP(C9,'Liste chauffeur'!$B$5:$L$19,2,TRUE)&" "&VLOOKUP(C9,'Liste chauffeur'!$B$5:$L$19,3,TRUE) -> ATTOUMANI Kamaldine | E9: =Horaire!C9 -> 13 ARRETS | G9: =COUNTBLANK(F9) -> 1 | M9: =IF(G9=1,"",K9-F9) | N9: =J9 -> 0 | O9: =IF(G9=1,0,O$6) -> 0 | P9: =IF(O9=0,0,N9/O9) -> 0
A10: =Horaire!A10 -> CHM | B10: =Horaire!E10 -> 0.25 | C10: =Horaire!H10 -> H3 | D10: =VLOOKUP(C10,'Liste chauffeur'!$B$5:$L$19,2,TRUE)&" "&VLOOKUP(C10,'Liste chauffeur'!$B$5:$L$19,3,TRUE) -> SAID ALI Kamile | E10: =Horaire!C10 -> 13 ARRETS | G10: =COUNTBLANK(F10) -> 1 | M10: =IF(G10=1,"",K10-F10) | N10: =J10 -> 0 | O10: =IF(G10=1,0,O$6) -> 0 | P10: =IF(O10=0,0,N10/O10) -> 0
A11: =Horaire!A11 -> CHM | B11: =Horaire!E11 -> 0.27083333 | C11: =Horaire!H11 -> H1 | D11: =VLOOKUP(C11,'Liste chauffeur'!$B$5:$L$19,2,TRUE)&" "&VLOOKUP(C11,'Liste chauffeur'!$B$5:$L$19,3,TRUE) -> CHADHOULI Houmadi | E11: =Horaire!C11 -> 13 ARRETS | G11: =COUNTBLANK(F11) -> 1 | M11: =IF(G11=1,"",K11-F11) | N11: =J11 -> 0 | O11: =IF(G11=1,0,O$6) -> 0 | P11: =IF(O11=0,0,N11/O11) -> 0
A12: =Horaire!A12 -> LA BARGE | B12: =Horaire!E12 -> 0.27083333 | C12: =Horaire!H12 -> H3 | D12: =VLOOKUP(C12,'Liste chauffeur'!$B$5:$L$19,2,TRUE)&" "&VLOOKUP(C12,'Liste chauffeur'!$B$5:$L$19,3,TRUE) -> SAID ALI Kamile | E12: =Horaire!C12 -> DIRECT | G12: =COUNTBLANK(F12) -> 1 | M12: =IF(G12=1,"",K12-F12) | N12: =J12 -> 0 | O12: =IF(G12=1,0,O$6) -> 0 | P12: =IF(O12=0,0,N12/O12) -> 0
A13: =Horaire!A13 -> LA BARGE | B13: =Horaire!E13 -> 0.27083333 | C13: =Horaire!H13 -> H5 | D13: =VLOOKUP(C13,'Liste chauffeur'!$B$5:$L$19,2,TRUE)&" "&VLOOKUP(C13,'Liste chauffeur'!$B$5:$L$19,3,TRUE) -> ATTOUMANI Kamaldine | E13: =Horaire!C13 -> DIRECT+CRA | G13: =COUNTBLANK(F13) -> 1 | M13: =IF(G13=1,"",K13-F13) | N13: =J13 -> 0 | O13: =IF(G13=1,0,O$6) -> 0 | P13: =IF(O13=0,0,N13/O13) -> 0
A14: =Horaire!A14 -> CHM | B14: =Horaire!E14 -> 0.28819444 | C14: =Horaire!H14 -> H1 | D14: =VLOOKUP(C14,'Liste chauffeur'!$B$5:$L$19,2,TRUE)&" "&VLOOKUP(C14,'Liste chauffeur'!$B$5:$L$19,3,TRUE) -> CHADHOULI Houmadi | E14: =Horaire!C14 -> DIRECT | G14: =COUNTBLANK(F14) -> 1 | M14: =IF(G14=1,"",K14-F14) | N14: =J14 -> 0 | O14: =IF(G14=1,0,O$6) -> 0 | P14: =IF(O14=0,0,N14/O14) -> 0
A15: =Horaire!A15 -> CHM | B15: =Horaire!E15 -> 0.28472222 | C15: =Horaire!H15 -> H5 | D15: =VLOOKUP(C15,'Liste chauffeur'!$B$5:$L$19,2,TRUE)&" "&VLOOKUP(C15,'Liste chauffeur'!$B$5:$L$19,3,TRUE) -> ATTOUMANI Kamaldine | E15: =Horaire!C15 -> DIRECT | G15: =COUNTBLANK(F15) -> 1 | M15: =IF(G15=1,"",K15-F15) | N15: =J15 -> 0 | O15: =IF(G15=1,0,O$6) -> 0 | P15: =IF(O15=0,0,N15/O15) -> 0
A16: =Horaire!A16 -> LA BARGE | B16: =Horaire!E16 -> 0.29513889 | C16: =Horaire!H16 -> H3 | D16: =VLOOKUP(C16,'Liste chauffeur'!$B$5:$L$19,2,TRUE)&" "&VLOOKUP(C16,'Liste chauffeur'!$B$5:$L$19,3,TRUE) -> SAID ALI Kamile | E16: =Horaire!C16 -> DIRECT+CRA | G16: =COUNTBLANK(F16) -> 1 | M16: =IF(G16=1,"",K16-F16) | N16: =J16 -> 0 | O16: =IF(G16=1,0,O$6) -> 0 | P16: =IF(O16=0,0,N16/O16) -> 0
A17: =Horaire!A17 -> LA BARGE | B17: =Horaire!E17 -> 0.3125 | C17: =Horaire!H17 -> H5 | D17: =VLOOKUP(C17,'Liste chauffeur'!$B$5:$L$19,2,TRUE)&" "&VLOOKUP(C17,'Liste chauffeur'!$B$5:$L$19,3,TRUE) -> ATTOUMANI Kamaldine | E17: =Horaire!C17 -> DIRECT | G17: =COUNTBLANK(F17) -> 1 | M17: =IF(G17=1,"",K17-F17) | N17: =J17 -> 0 | O17: =IF(G17=1,0,O$6) -> 0 | P17: =IF(O17=0,0,N17/O17) -> 0
A18: =Horaire!A18 -> CHM | B18: =Horaire!E18 -> 0.32638889 | C18: =Horaire!H18 -> H5 | D18: =VLOOKUP(C18,'Liste chauffeur'!$B$5:$L$19,2,TRUE)&" "&VLOOKUP(C18,'Liste chauffeur'!$B$5:$L$19,3,TRUE) -> ATTOUMANI Kamaldine | E18: =Horaire!C18 -> DIRECT | G18: =COUNTBLANK(F18) -> 1 | N18: =J18 -> 0 | O18: =IF(G18=1,0,O$6) -> 0 | P18: =IF(O18=0,0,N18/O18) -> 0
A19: =Horaire!A19 -> LA BARGE | B19: =Horaire!E19 -> 0.32638889 | C19: =Horaire!H19 -> H1 | D19: =VLOOKUP(C19,'Liste chauffeur'!$B$5:$L$19,2,TRUE)&" "&VLOOKUP(C19,'Liste chauffeur'!$B$5:$L$19,3,TRUE) -> CHADHOULI Houmadi | E19: =Horaire!C19 -> DIRECT | G19: =COUNTBLANK(F19) -> 1 | N19: =J19 -> 0 | O19: =IF(G19=1,0,O$6) -> 0 | P19: =IF(O19=0,0,N19/O19) -> 0
B20: NON PLANIFIE | G20: =COUNTBLANK(F20) -> 1 | N20: =J20 -> 0 | O20: =IF(G20=1,0,O$6) -> 0 | P20: =IF(O20=0,0,N20/O20) -> 0
B21: NON PLANIFIE | G21: =COUNTBLANK(F21) -> 1 | N21: =J21 -> 0 | O21: =IF(G21=1,0,O$6) -> 0 | P21: =IF(O21=0,0,N21/O21) -> 0
B22: NON PLANIFIE | G22: =COUNTBLANK(F22) -> 1 | N22: =J22 -> 0 | O22: =IF(G22=1,0,O$6) -> 0 | P22: =IF(O22=0,0,N22/O22) -> 0
B23: ST1 | G23: =SUM(G8:G19) -> 12 | H23: =SUM(H8:H18) -> 0 | M23: =AVERAGE(M8:M18) -> #DIV/0! | N23: =SUM(N8:N22) -> 0 | O23: =SUM(O8:O22) -> 0 | P23: =N23/O23 -> #DIV/0!
A24: =Horaire!A20 -> LA BARGE | B24: =Horaire!E20 -> 0.58333333 | C24: =Horaire!H20 -> H1 | D24: =VLOOKUP(C24,'Liste chauffeur'!$B$5:$L$19,2,TRUE)&" "&VLOOKUP(C24,'Liste chauffeur'!$B$5:$L$19,3,TRUE) -> CHADHOULI Houmadi | E24: =Horaire!C20 -> 13 ARRETS | G24: =COUNTBLANK(F24) -> 1 | M24: =IF(G24=1,"",K24-F24) | N24: =J24 -> 0 | O24: =IF(G24=1,0,O$6) -> 0 | P24: =IF(O24=0,0,N24/O24) -> 0
A25: =Horaire!A21 -> CHM | B25: =Horaire!E21 -> 0.58333333 | C25: =Horaire!H21 -> H3 | D25: =VLOOKUP(C25,'Liste chauffeur'!$B$5:$L$19,2,TRUE)&" "&VLOOKUP(C25,'Liste chauffeur'!$B$5:$L$19,3,TRUE) -> SAID ALI Kamile | E25: =Horaire!C21 -> DIRECT | G25: =COUNTBLANK(F25) -> 1 | M25: =IF(G25=1,"",K25-F25) | N25: =J25 -> 0 | O25: =IF(G25=1,0,O$6) -> 0 | P25: =IF(O25=0,0,N25/O25) -> 0
A26: =Horaire!A22 -> LA BARGE | B26: =Horaire!E22 -> 0.61458333 | C26: =Horaire!H22 -> H1 | D26: =VLOOKUP(C26,'Liste chauffeur'!$B$5:$L$19,2,TRUE)&" "&VLOOKUP(C26,'Liste chauffeur'!$B$5:$L$19,3,TRUE) -> CHADHOULI Houmadi | E26: =Horaire!C22 -> 13 ARRETS | G26: =COUNTBLANK(F26) -> 1 | M26: =IF(G26=1,"",K26-F26) | N26: =J26 -> 0 | O26: =IF(G26=1,0,O$6) -> 0 | P26: =IF(O26=0,0,N26/O26) -> 0
A27: =Horaire!A23 -> LA BARGE | B27: =Horaire!E23 -> 0.61805556 | C27: =Horaire!H23 -> H3 | D27: =VLOOKUP(C27,'Liste chauffeur'!$B$5:$L$19,2,TRUE)&" "&VLOOKUP(C27,'Liste chauffeur'!$B$5:$L$19,3,TRUE) -> SAID ALI Kamile | E27: =Horaire!C23 -> 13 ARRETS | G27: =COUNTBLANK(F27) -> 1 | M27: =IF(G27=1,"",K27-F27) | N27: =J27 -> 0 | O27: =IF(G27=1,0,O$6) -> 0 | P27: =IF(O27=0,0,N27/O27) -> 0
A28: =Horaire!A24 -> CHM | B28: =Horaire!E24 -> 0.625 | C28: =Horaire!H24 -> H5 | D28: =VLOOKUP(C28,'Liste chauffeur'!$B$5:$L$19,2,TRUE)&" "&VLOOKUP(C28,'Liste chauffeur'!$B$5:$L$19,3,TRUE) -> ATTOUMANI Kamaldine | E28: =Horaire!C24 -> DIRECT | G28: =COUNTBLANK(F28) -> 1 | M28: =IF(G28=1,"",K28-F28) | N28: =J28 -> 0 | O28: =IF(G28=1,0,O$6) -> 0 | P28: =IF(O28=0,0,N28/O28) -> 0
A29: =Horaire!A25 -> LA BARGE | B29: =Horaire!E25 -> 0.63888889 | C29: =Horaire!H25 -> H1 | D29: =VLOOKUP(C29,'Liste chauffeur'!$B$5:$L$19,2,TRUE)&" "&VLOOKUP(C29,'Liste chauffeur'!$B$5:$L$19,3,TRUE) -> CHADHOULI Houmadi | E29: =Horaire!C25 -> 13 ARRETS | G29: =COUNTBLANK(F29) -> 1 | M29: =IF(G29=1,"",K29-F29) | N29: =J29 -> 0 | O29: =IF(G29=1,0,O$6) -> 0 | P29: =IF(O29=0,0,N29/O29) -> 0
A30: =Horaire!A26 -> LA BARGE | B30: =Horaire!E26 -> 0.65972222 | C30: =Horaire!H26 -> H5 | D30: =VLOOKUP(C30,'Liste chauffeur'!$B$5:$L$19,2,TRUE)&" "&VLOOKUP(C30,'Liste chauffeur'!$B$5:$L$19,3,TRUE) -> ATTOUMANI Kamaldine | E30: =Horaire!C26 -> 13 ARRETS | G30: =COUNTBLANK(F30) -> 1 | N30: =J30 -> 0 | O30: =IF(G30=1,0,O$6) -> 0 | P30: =IF(O30=0,0,N30/O30) -> 0
A31: =Horaire!A27 -> LA BARGE | B31: =Horaire!E27 -> 0.6875 | C31: =Horaire!H27 -> H5 | D31: =VLOOKUP(C31,'Liste chauffeur'!$B$5:$L$19,2,TRUE)&" "&VLOOKUP(C31,'Liste chauffeur'!$B$5:$L$19,3,TRUE) -> ATTOUMANI Kamaldine | E31: =Horaire!C27 -> 13 ARRETS | G31: =COUNTBLANK(F31) -> 1 | N31: =J31 -> 0 | O31: =IF(G31=1,0,O$6) -> 0 | P31: =IF(O31=0,0,N31/O31) -> 0
A32: =Horaire!A28 -> LA BARGE | B32: =Horaire!E28 -> 0.71180556 | C32: =Horaire!H28 -> H5 | D32: =VLOOKUP(C32,'Liste chauffeur'!$B$5:$L$19,2,TRUE)&" "&VLOOKUP(C32,'Liste chauffeur'!$B$5:$L$19,3,TRUE) -> ATTOUMANI Kamaldine | E32: =Horaire!C28 -> 13 ARRETS | G32: =COUNTBLANK(F32) -> 1 | N32: =J32 -> 0 | O32: =IF(G32=1,0,O$6) -> 0 | P32: =IF(O32=0,0,N32/O32) -> 0
A33: =Horaire!A29 -> LA BARGE | B33: =Horaire!E29 -> 0.76041667 | C33: =Horaire!H29 -> H3 | D33: =VLOOKUP(C33,'Liste chauffeur'!$B$5:$L$19,2,TRUE)&" "&VLOOKUP(C33,'Liste chauffeur'!$B$5:$L$19,3,TRUE) -> SAID ALI Kamile | E33: =Horaire!C29 -> DIRECT | G33: =COUNTBLANK(F33) -> 1 | N33: =J33 -> 0 | O33: =IF(G33=1,0,O$6) -> 0 | P33: =IF(O33=0,0,N33/O33) -> 0
A34: =Horaire!A30 -> CHM | B34: =Horaire!E30 -> 0.76041667 | C34: =Horaire!H30 -> H1 | D34: =VLOOKUP(C34,'Liste chauffeur'!$B$5:$L$19,2,TRUE)&" "&VLOOKUP(C34,'Liste chauffeur'!$B$5:$L$19,3,TRUE) -> CHADHOULI Houmadi | E34: =Horaire!C30 -> DIRECT | G34: =COUNTBLANK(F34) -> 1 | N34: =J34 -> 0 | O34: =IF(G34=1,0,O$6) -> 0 | P34: =IF(O34=0,0,N34/O34) -> 0
A35: =Horaire!A31 -> LA BARGE | B35: =Horaire!E31 -> 0.78125 | C35: =Horaire!H31 -> H1 | D35: =VLOOKUP(C35,'Liste chauffeur'!$B$5:$L$19,2,TRUE)&" "&VLOOKUP(C35,'Liste chauffeur'!$B$5:$L$19,3,TRUE) -> CHADHOULI Houmadi | E35: =Horaire!C31 -> 13 ARRETS | G35: =COUNTBLANK(F35) -> 1 | N35: =J35 -> 0 | O35: =IF(G35=1,0,O$6) -> 0 | P35: =IF(O35=0,0,N35/O35) -> 0
A36: =Horaire!A32 -> CHM | B36: =Horaire!E32 -> 0.78125 | C36: =Horaire!H32 -> H3 | D36: =VLOOKUP(C36,'Liste chauffeur'!$B$5:$L$19,2,TRUE)&" "&VLOOKUP(C36,'Liste chauffeur'!$B$5:$L$19,3,TRUE) -> SAID ALI Kamile | E36: =Horaire!C32 -> DIRECT | G36: =COUNTBLANK(F36) -> 1 | N36: =J36 -> 0 | O36: =IF(G36=1,0,O$6) -> 0 | P36: =IF(O36=0,0,N36/O36) -> 0
A37: =Horaire!A33 -> LA BARGE | B37: =Horaire!E33 -> 0.80208333 | C37: =Horaire!H33 -> H3 | D37: =VLOOKUP(C37,'Liste chauffeur'!$B$5:$L$19,2,TRUE)&" "&VLOOKUP(C37,'Liste chauffeur'!$B$5:$L$19,3,TRUE) -> SAID ALI Kamile | E37: =Horaire!C33 -> 13 ARRETS | G37: =COUNTBLANK(F37) -> 1 | N37: =J37 -> 0 | O37: =IF(G37=1,0,O$6) -> 0 | P37: =IF(O37=0,0,N37/O37) -> 0
A38: =Horaire!A34 -> CRA+CHM | B38: =Horaire!E34 -> 0.80902778 | C38: =Horaire!H34 -> H1 | D38: =VLOOKUP(C38,'Liste chauffeur'!$B$5:$L$19,2,TRUE)&" "&VLOOKUP(C38,'Liste chauffeur'!$B$5:$L$19,3,TRUE) -> CHADHOULI Houmadi | E38: =Horaire!C34 -> DIRECT+CRA | G38: =COUNTBLANK(F38) -> 1 | N38: =J38 -> 0 | O38: =IF(G38=1,0,O$6) -> 0 | P38: =IF(O38=0,0,N38/O38) -> 0
A39: =Horaire!A35 -> LA BARGE | B39: =Horaire!E35 -> 0.82291667 | C39: =Horaire!H35 -> H3 | D39: =VLOOKUP(C39,'Liste chauffeur'!$B$5:$L$19,2,TRUE)&" "&VLOOKUP(C39,'Liste chauffeur'!$B$5:$L$19,3,TRUE) -> SAID ALI Kamile | E39: =Horaire!C35 -> 13 ARRETS | G39: =COUNTBLANK(F39) -> 1 | N39: =J39 -> 0 | O39: =IF(G39=1,0,O$6) -> 0 | P39: =IF(O39=0,0,N39/O39) -> 0
B40: NON PLANIFIE
B41: NON PLANIFIE
...

Sheet H1
G1: ù
A2: TYPE | B2: H1
A3: DATE | B3: 45627
A4: CHAUFFEUR | B4: =VLOOKUP(B2,'Liste chauffeur'!$B$5:$L$19,2,TRUE)&" "&VLOOKUP(B2,'Liste chauffeur'!$B$5:$L$19,3,TRUE) -> CHADHOULI Houmadi | L4: 46143
K6: ARRIVEE | O6: 8
A7: LIEU DE DEPART | B7: Heure théorique départ | C7: Horaire | D7: Chauffeur | E7: Direct/Non Direct | F7: Heure réelle départ | G7: Trajet non effectué | H7: Départ avec plus de 10 mns retard | I7: Nbre personnes montée | J7: Nbre personnes descente | K7: Heure arrivée finale | L7: Commentaires | M7: Temps Aller | N7: Nbre personnes moyenne | O7: Capacité max | P7: Taux Fréquentation
A8: CHM | B8: 0.23263889 | C8: H1 | D8: CHADHOULI Houmadi | E8: 13 ARRETS | G8: 1 | M8: =IF(G8=1,"",K8-F8) | N8: =J8 -> 0 | O8: =IF(G8=1,0,O$6) -> 0 | P8: =IF(O8=0,0,N8/O8) -> 0
A9: CHM | B9: 0.27083333 | C9: H1 | D9: CHADHOULI Houmadi | E9: 13 ARRETS | G9: 1 | M9: =IF(G9=1,"",K9-F9) | N9: =J9 -> 0 | O9: =IF(G9=1,0,O$6) -> 0 | P9: =IF(O9=0,0,N9/O9) -> 0
A10: CHM | B10: 0.28819444 | C10: H1 | D10: CHADHOULI Houmadi | E10: DIRECT | G10: 1 | M10: =IF(G10=1,"",K10-F10) | N10: =J10 -> 0 | O10: =IF(G10=1,0,O$6) -> 0 | P10: =IF(O10=0,0,N10/O10) -> 0
A11: LA BARGE | B11: 0.58333333 | C11: H1 | D11: CHADHOULI Houmadi | E11: 13 ARRETS | G11: 1 | M11: =IF(G11=1,"",K11-F11) | N11: =J11 -> 0 | O11: =IF(G11=1,0,O$6) -> 0 | P11: =IF(O11=0,0,N11/O11) -> 0
A12: LA BARGE | B12: 0.61458333 | C12: H1 | D12: CHADHOULI Houmadi | E12: 13 ARRETS | G12: 1 | M12: =IF(G12=1,"",K12-F12) | N12: =J12 -> 0 | O12: =IF(G12=1,0,O$6) -> 0 | P12: =IF(O12=0,0,N12/O12) -> 0
A13: LA BARGE | B13: 0.63888889 | C13: H1 | D13: CHADHOULI Houmadi | E13: 13 ARRETS | G13: 1 | M13: =IF(G13=1,"",K13-F13) | N13: =J13 -> 0 | O13: =IF(G13=1,0,O$6) -> 0 | P13: =IF(O13=0,0,N13/O13) -> 0
A14: REMPLACEMENT | C14: H | M14: =IF(G14=1,"",K14-F14) -> 0 | N14: =J14 -> 0 | O14: =IF(G14=1,0,O$6) -> 8 | P14: =IF(O14=0,0,N14/O14) -> 0
A15: REMPLACEMENT | C15: H | M15: =IF(G15=1,"",K15-F15) -> 0 | N15: =J15 -> 0 | O15: =IF(G15=1,0,O$6) -> 8 | P15: =IF(O15=0,0,N15/O15) -> 0
A16: REMPLACEMENT | C16: H | M16: =IF(G16=1,"",K16-F16) -> 0 | N16: =J16 -> 0 | O16: =IF(G16=1,0,O$6) -> 8 | P16: =IF(O16=0,0,N16/O16) -> 0
A17: REMPLACEMENT | C17: H | N17: =J17 -> 0 | O17: =IF(G17=1,0,O$6) -> 8 | P17: =IF(O17=0,0,N17/O17) -> 0
A18: REMPLACEMENT | C18: H | N18: =J18 -> 0 | O18: =IF(G18=1,0,O$6) -> 8
C19: S | F19: Signature Chauffeur
A21: TYPE | B21: H1
A22: CHAUFFEUR | B22: CHADHOULI Houmadi | L22: =L4+1 -> 46144
K24: ARRIVEE
A25: LIEU DE DEPART | B25: Heure théorique départ | C25: Horaire | D25: Chauffeur | E25: Direct/Non Direct | F25: Heure réelle départ | G25: Trajet non effectué | H25: Départ avec plus de 10 mns retard | I25: Nbre personnes montée | J25: Nbre personnes descente | K25: Heure arrivée finale | L25: Commentaires
A26: CHM | B26: 0.23263889 | C26: H1 | D26: CHADHOULI Houmadi | E26: 13 ARRETS | G26: 1
A27: CHM | B27: 0.27083333 | C27: H1 | D27: CHADHOULI Houmadi | E27: 13 ARRETS | G27: 1
A28: CHM | B28: 0.28819444 | C28: H1 | D28: CHADHOULI Houmadi | E28: DIRECT | G28: 1
A29: LA BARGE | B29: 0.32638889 | C29: H1 | D29: CHADHOULI Houmadi | E29: DIRECT | G29: 1
A30: LA BARGE | B30: 0.58333333 | C30: H1 | D30: CHADHOULI Houmadi | E30: 13 ARRETS | G30: 1
A31: LA BARGE | B31: 0.61458333 | C31: H1 | D31: CHADHOULI Houmadi | E31: 13 ARRETS | G31: 1
A32: LA BARGE | B32: 0.63888889 | C32: H1 | D32: CHADHOULI Houmadi | E32: 13 ARRETS | G32: 1
A33: CHM | B33: 0.76041667 | C33: H1 | D33: CHADHOULI Houmadi | E33: DIRECT | G33: 1
A34: LA BARGE | B34: 0.78125 | C34: H1 | D34: CHADHOULI Houmadi | E34: 13 ARRETS | G34: 1
A35: CRA+CHM | B35: 0.80902778 | C35: H1 | D35: CHADHOULI Houmadi | E35: DIRECT+CRA | G35: 1
A36: REMPLACEMENT | C36: H
A37: REMPLACEMENT | C37: H
A38: REMPLACEMENT | C38: H
A39: REMPLACEMENT | C39: H
C41: S | F41: Signature Chauffeur
A42: TYPE | B42: H1
A43: CHAUFFEUR | B43: CHADHOULI Houmadi | L43: =L22+1 -> 46145
K45: ARRIVEE
...

Sheet H3B
G1: ù
A2: TYPE | B2: H3
A3: DATE | B3: =#REF! -> #REF!
A4: CHAUFFEUR | B4: =VLOOKUP(B2,'Liste chauffeur'!$B$5:$L$19,2,TRUE)&" "&VLOOKUP(B2,'Liste chauffeur'!$B$5:$L$19,3,TRUE) -> SAID ALI Kamile | L4: 46143
K6: ARRIVEE | O6: 8
A7: LIEU DE DEPART | B7: Heure théorique départ | C7: Horaire | D7: Chauffeur | E7: Direct/Non Direct | F7: Heure réelle départ | G7: Trajet non effectué | H7: Départ avec plus de 10 mns retard | I7: Nbre personnes montée | J7: Nbre personnes descente | K7: Heure arrivée finale | L7: Commentaires | M7: Temps Aller | N7: Nbre personnes moyenne | O7: Capacité max | P7: Taux Fréquentation
A8: CHM | B8: 0.25 | C8: H3 | D8: SAID ALI Kamile | E8: 13 ARRETS | G8: 1 | M8: =IF(G8=1,"",K8-F8) | N8: =J8 -> 0 | O8: =IF(G8=1,0,O$6) -> 0 | P8: =IF(O8=0,0,N8/O8) -> 0
