Workbook

Sheet Feuil1
A3: DATE
A4: CHAUFFEUR
E6: Arrêt 1 | I6: Arrêt 2 | M6: Arrêt 3 | Q6: PEM PASSAMAINTY
B7: Heure théorique départ | C7: Heure réelle départ | D7: Nbre personnes + | E7: Nbre personnes + | F7: Nbre personnes - | G7: Heure arrivée arrêt 1 | H7: Délai | I7: Nbre personnes + | J7: Nbre personnes - | K7: Heure arrivée arrêt 2 | L7: Délai | M7: Nbre personnes + | N7: Nbre personnes - | O7: Heure arrivée arrêt 3 | P7: Délai | Q7: Nbre personnes - | S7: Heure arrivée finale | T7: Commentaires | U7: Temps Aller
A8: VAHIBE | B8: 0.20833333 | H8: =G8-C8 -> 0 | L8: =K8-G8 -> 0 | P8: =O8-K8 -> 0 | R8: =IF(D8+E8-F8+I8-J8+M8-N8=Q8,"OK",D8+E8-F8+I8-J8+M8-N8-Q8) -> OK | U8: =S8-C8 -> 0
A9: VAHIBE | B9: 0.21527778 | H9: =G9-C9 -> 0 | L9: =K9-G9 -> 0 | P9: =O9-K9 -> 0 | U9: =S9-C9 -> 0
A10: VAHIBE | B10: 0.22222222 | H10: =G10-C10 -> 0 | L10: =K10-G10 -> 0 | P10: =O10-K10 -> 0 | U10: =S10-C10 -> 0
A11: VAHIBE | B11: 0.22916667 | H11: =G11-C11 -> 0 | L11: =K11-G11 -> 0 | P11: =O11-K11 -> 0 | U11: =S11-C11 -> 0
A12: VAHIBE | B12: 0.23611111 | H12: =G12-C12 -> 0 | L12: =K12-G12 -> 0 | P12: =O12-K12 -> 0 | U12: =S12-C12 -> 0
A13: VAHIBE | B13: 0.24305556 | H13: =G13-C13 -> 0 | L13: =K13-G13 -> 0 | P13: =O13-K13 -> 0 | U13: =S13-C13 -> 0
A14: VAHIBE | B14: 0.25 | H14: =G14-C14 -> 0 | L14: =K14-G14 -> 0 | P14: =O14-K14 -> 0 | U14: =S14-C14 -> 0
A15: VAHIBE | B15: 0.25694444 | H15: =G15-C15 -> 0 | L15: =K15-G15 -> 0 | P15: =O15-K15 -> 0 | U15: =S15-C15 -> 0
A16: VAHIBE | B16: 0.26388889 | H16: =G16-C16 -> 0 | L16: =K16-G16 -> 0 | P16: =O16-K16 -> 0 | U16: =S16-C16 -> 0
A17: VAHIBE | B17: 0.27083333 | H17: =G17-C17 -> 0 | L17: =K17-G17 -> 0 | P17: =O17-K17 -> 0 | U17: =S17-C17 -> 0
A18: VAHIBE | B18: 0.27777778 | H18: =G18-C18 -> 0 | L18: =K18-G18 -> 0 | P18: =O18-K18 -> 0 | U18: =S18-C18 -> 0
A19: VAHIBE | B19: 0.28472222 | H19: =G19-C19 -> 0 | L19: =K19-G19 -> 0 | P19: =O19-K19 -> 0 | U19: =S19-C19 -> 0
A20: VAHIBE | B20: 0.29166667 | H20: =G20-C20 -> 0 | L20: =K20-G20 -> 0 | P20: =O20-K20 -> 0 | U20: =S20-C20 -> 0
... A26: VAHIBE | B26: 0.33333333 | H26: =G26-C26 -> 0 | L26: =K26-G26 -> 0 | P26: =O26-K26 -> 0 | U26: =S26-C26 -> 0
Q27: VAHIBE | U27: =SUM(U8:U26) -> 0
A28: PEM PASSAMAINTY | B28: 0.625 | H28: =G28-C28 -> 0 | L28: =K28-G28 -> 0 | P28: =O28-K28 -> 0 | U28: =S28-C28 -> 0
A29: PEM PASSAMAINTY | B29: 0.63194444 | H29: =G29-C29 -> 0 | L29: =K29-G29 -> 0 | P29: =O29-K29 -> 0 | U29: =S29-C29 -> 0
A30: PEM PASSAMAINTY | B30: 0.63888889 | H30: =G30-C30 -> 0 | L30: =K30-G30 -> 0 | P30: =O30-K30 -> 0 | U30: =S30-C30 -> 0
A31: PEM PASSAMAINTY | B31: 0.64583333 | H31: =G31-C31 -> 0 | L31: =K31-G31 -> 0 | P31: =O31-K31 -> 0 | U31: =S31-C31 -> 0
A32: PEM PASSAMAINTY | B32: 0.65277778 | H32: =G32-C32 -> 0 | L32: =K32-G32 -> 0 | P32: =O32-K32 -> 0 | U32: =S32-C32 -> 0
A33: PEM PASSAMAINTY | B33: 0.65972222 | H33: =G33-C33 -> 0 | L33: =K33-G33 -> 0 | P33: =O33-K33 -> 0 | U33: =S33-C33 -> 0
A34: PEM PASSAMAINTY | B34: 0.66666667 | H34: =G34-C34 -> 0 | L34: =K34-G34 -> 0 | P34: =O34-K34 -> 0 | U34: =S34-C34 -> 0
A35: PEM PASSAMAINTY | B35: 0.67361111 | H35: =G35-C35 -> 0 | L35: =K35-G35 -> 0 | P35: =O35-K35 -> 0 | U35: =S35-C35 -> 0
A36: PEM PASSAMAINTY | B36: 0.68055556 | H36: =G36-C36 -> 0 | L36: =K36-G36 -> 0 | P36: =O36-K36 -> 0 | U36: =S36-C36 -> 0
A37: PEM PASSAMAINTY | B37: 0.6875 | H37: =G37-C37 -> 0 | L37: =K37-G37 -> 0 | P37: =O37-K37 -> 0 | U37: =S37-C37 -> 0
A38: PEM PASSAMAINTY | B38: 0.69444444 | H38: =G38-C38 -> 0 | L38: =K38-G38 -> 0 | P38: =O38-K38 -> 0 | U38: =S38-C38 -> 0
A39: PEM PASSAMAINTY | B39: 0.70138889 | H39: =G39-C39 -> 0 | L39: =K39-G39 -> 0 | P39: =O39-K39 -> 0 | U39: =S39-C39 -> 0
... A46: PEM PASSAMAINTY | B46: 0.75 | H46: =G46-C46 -> 0 | L46: =K46-G46 -> 0 | P46: =O46-K46 -> 0 | U46: =S46-C46 -> 0
U47: =SUM(U28:U46) -> 0
U48: =U47+U27 -> 0
C49: Signature Chauffeur | I49: Signature Coordinateur

Sheet REUNION DU 28.04
B1: N° | C1: CADEMA | D1: STATUT | E1: LICENCE TRANSPORTEUR | F1: SIREN LICENCE | G1: VALIDITE LICENCE TRANSP | H1: N° | I1: N° Chauffeur | J1: Type | K1: Nom | L1: Prénom | M1: Téléphone | N1: Mail | O1: Siret | P1: Secteur d'activité | Q1: N° licence | R1: CARTE CONDUCTEUR | S1: VALIDITE CARTE CONDUCTEUR | T1: N° IMMATRICULATION CARTE GRISE | U1: DATE IMMATRICULATION | V1: AGE DU VEHICULE | W1: Type de vehicule | X1: ETAT VEHICULE | Y1: RDV MAY EQUIP | Z1: HABILLAGE | AA1: REGLT HABILLAGE | AB1: EQUIPEMENT | AC1: HABILLAGE 2021 | AD1: HABILLAGE 2023 | AE1: IDENTITE | AF1: NATIONALITE | AG1: VALIDITE CARTE SEJOUR | AH1: CARTE VITALE | AI1: ASSURANCES | AJ1: FACTURE _3 MOIS | AK1: IMPOTS | AL1: PHOTO | AM1: N° AGC | AN1: Capital souscrit | AO1: Année de souscription | AP1: Cotisations versées en 2021 | AQ1: COTISATIONS 2023 | AR1: COTISATIONS 2024 | AS1: N° Rue | AT1: Adresse | AU1: Code postal | AV1: Commune | AW1: REMARQUES
A2: 1 | B2: 11 | C2: CADEMA 1 | D2: AO | E2: NON | F2: - | G2: - | H2: 1 | I2: C4 | J2: C2 | K2: ABDOU MINIHADJI | L2: Amada | M2: 0639 65 03 93 | N2: abdouminihadjiamada@hotmail.com | O2: 066 311 101 000 19 | P2: Centre Sud | Q2: 976-CS-057 | R2: 505 | S2: 45305 | T2: FY-654-BF | U2: 44279 | V2: =2024-YEAR(U2) -> 3 | W2: 9 PLACES | X2: BON | Z2: OUI | AA2: _ | AB2: NON | AC2: OUI | AE2: 43262 | AF2: F | AG2: _ | AH2: NON | AI2: NON | AJ2: 2020 | AL2: OUI | AM2: 2020/13 | AN2: 510 | AO2: 43466 | AP2: 450 | AS2: 64 | AT2: Avenue de rassi | AU2: 97670 | AV2: Chiconi | AW2: ancien gérant - Habillage 2021
A3: 33 | B3: 17 | C3: CADEMA 1 | D3: AO | E3: NON | F3: - | G3: - | H3: 2 | I3: C6 | J3: C10 | K3: ADINANI | L3: Zoubert | M3: 0639 25 77 76 | N3: zoubert.adinani2@gmail.com | O3: 799 358 700 00018 | P3: Mamoudzou | Q3: 976-M-447 | R3: 1050 | S3: 46342 | T3: GR-407-DV | U3: 45182 | V3: =2024-YEAR(U3) -> 1 | W3: 9 PLACES | X3: BON | Y3: 45406 | Z3: NON | AA3: OUI | AB3: NON | AC3: NON | AD3: A venir | AE3: 48415 | AF3: F | AG3: _ | AH3: OUI | AI3: OUI | AJ3: OUI | AK3: 2022 | AL3: OUI | AN3: 510 | AO3: 43466 | AP3: 250 | AQ3: NON | AR3: NON | AT3: Tahiti plage route de poroani | AU3: 97640 | AV3: Sada | AW3: attente débolacge prêt
A4: 65 | B4: 23 | C4: CADEMA 1 | D4: AO | E4: NON | F4: - | G4: - | H4: 3 | J4: C14 | K4: ALI ATTOUMANI | L4: Bacar | M4: 0639 87 21 88 | N4: aattoumani.bacar@gmail.com | O4: 024 068 413 00020 | P4: Mamoudzou | Q4: 976-M-116 | R4: 222 | S4: 45489 | T4: FJ-886-VX | U4: 43707 | W4: 9 PLACES | Z4: A MOITIE | AA4: NON | AC4: OUI PAS PAYE | AE4: 45896 | AF4: F | AH4: NON | AI4: NON | AJ4: NON | AK4: NON | AL4: OUI | AN4: 510 | AO4: 43466 | AP4: 150 | AQ4: NON | AR4: NON | AS4: 4 | AT4: Chemin ma ali andy | AU4: 97640 | AV4: Sada | AW4: Voiture endommagé d'un coté et la tete de taxi aussi habillé en 2021
A5: 129 | B5: 35 | C5: CADEMA 1 | D5: AO | E5: NON | F5: - | G5: - | H5: 4 | K5: ALLAOUI | L5: Inzoudine | M5: 0639 075923/0639 26 27 78 | N5: ambdihoumadi976@gmail.com | O5: 024 078 396 000 41 | P5: Mamoudzou | Q5: 976-M-049 | R5: 1294 | S5: 43992 | T5: GH-790-LS | U5: 44753 | V5: =2024-YEAR(U5) -> 2 | W5: 9 PLACES | Y5: ? Pas payé | Z5: NON | AA5: _ | AB5: NON | AE5: 47882 | AF5: F | AG5: _ | AH5: NON | AI5: NON | AJ5: NON | AK5: NON | AL5: NON | AM5: 2020/44 | AN5: 510 | AO5: 43466 | AP5: 450 | AS5: 85 | AT5: Rue younoussa bamana | AU5: 97640 | AV5: Sada | AW5: a une voiture neuve
A6: 161 | B6: 41 | C6: CADEMA 1 | D6: AO | E6: NON | F6: - | G6: - | H6: 5 | I6: voiture en panne | K6: ALLAOUI | L6: Soibrane | M6: 0639 65 31 82 | N6: stt653182@hotmail.com | O6: 024 043 30 000 11 | P6: Centre Sud | Q6: 976-CS-048 | R6: 806 | S6: 43222 | T6: FZ_148_HW | U6: 44336 | V6: =2024-YEAR(U6) -> 3 | W6: 9 PLACES | X6: OK | Y6: ? Pas payé | Z6: NON | AB6: NON | AC6: OUI | AE6: 46556 | AF6: F | AG6: _ | AH6: OUI | AI6: OUI | AJ6: OUI | AK6: OUI | AL6: OUI | AN6: 510 | AP6: 450 | AT6: Quartier Kami case impasse mavandzani | AU6: 97625 | AV6: Kani kéli | AW6: Il est pas eligible pour la demande de subvention
A7: 129 | B7: 35 | C7: CADEMA 1 | D7: AO | E7: NON | F7: - | G7: - | H7: 6 | J7: C6 | K7: AMBDI | L7: Houmadi | M7: 0639 23 55 69 | N7: ambdihoumadi976@gmail.com | O7: 066 312 224 000 26 | P7: Sud | Q7: 976-S-023 | R7: 759 | S7: 45639 | T7: GC-122-QA | U7: 44495 | V7: =2024-YEAR(U7) -> 3 | W7: 9 PLACES | X7: OK | Z7: OUI | AB7: OUI | AD7: OUI | AE7: 48640 | AF7: F | AG7: _ | AH7: OUI | AI7: OUI | AJ7: NON | AK7: 2022 | AL7: OUI | AM7: 2020/46 | AN7: 510 | AO7: 43466 | AP7: 250 | AQ7: NON | AR7: NON | AT7: Route nationale Mbouanatsa | AU7: 97620 | AV7: BOUENI | AW7: Habillage 2023
A8: 193 | B8: 47 | C8: CADEMA 1 | D8: AO | E8: NON | F8: - | G8: - | H8: 7 | I8: C9 | J8: C7 | K8: BINA HALADI | L8: Bina | M8: 0639 06 05 82 | N8: wonamaore@gmail.com | O8: 853 690 428 000 18 | P8: Sud | Q8: 976-S-045 | R8: 1414 | S8: 45181 | T8: GE-883-ES | U8: 44581 | V8: =2024-YEAR(U8) -> 2 | W8: 9 places | Z8: OUI | AA8: _ | AB8: OUI | AD8: OUI | AE8: 45040 | AF8: F | AG8: _ | AH8: OUI | AI8: 2023 | AJ8: OUI | AK8: 2022 | AL8: NON | AM8: 2020/61 | AN8: 510 | AO8: 44285 | AP8: 450 | AS8: 8 | AT8: Rue Said Fatima | AU8: 97640 | AV8: SADA | AW8: Habillage juin 2023
A9: 225 | B9: 53 | C9: CADEMA 1 | D9: AO | E9: NON | F9: - | G9: - | H9: 8 | J9: C12 | K9: BOINARIZIKI | L9: Zena Dhurari | M9: 0639 66 36 94 06 50 45 94 42 | N9: dhurari.transport@gmail.com | O9: 500 894 043 000 16 | P9: Centre Sud | Q9: 976-CS-071 | R9: 1000 | S9: 44349 | T9: FF-569-NF | U9: 43573 | V9: =2024-YEAR(U9) -> 5 | W9: 9 PLACES | Z9: NON | AA9: _ | AB9: NON | AE9: 45177 | AF9: F | AG9: _ | AH9: OUI | AI9: 2023 | AJ9: OUI | AK9: 2022 | AL9: OUI | AN9: 510 | AO9: 43466 | AP9: 250 | AS9: 97 | AT9: Rue du commerce | AU9: 97640 | AV9: Sada | AW9: voiture pas habillée
A10: 257 | B10: 59 | C10: CADEMA 1 | D10: AO | E10: NON | F10: - | G10: - | H10: 9 | I10: C3 | J10: C8 | K10: COMBO | L10: Said | M10: 0639 68 37 93 | N10: combosaid5@gmail.cpm | O10: 054 394 853 00029 | P10: Mamoudzou | Q10: 976-M-164 | R10: 920 | S10: 44871 | T10: GB-965-EQ | U10: 44419 | V10: =2024-YEAR(U10) -> 3 | W10: 9 PLACES | X10: NEUF | Y10: 45411 | Z10: NON | AA10: NON | AB10: NON | AC10: NON | AD10: NON | AE10: 49279 | AF10: F | AG10: _ | AH10: OUI | AI10: OUI | AJ10: 2024 | AK10: 2022 | AL10: NON | AM10: 2020/70 | AN10: 510 | AO10: 44295 | AP10: 100 | AQ10: NON | AR10: NON | AS10: 193 | AT10: Route Départementale | AU10: 97630 | AV10: Mtsamboro | AW10: Il a reçu sa subvention et il a rien payé, et il a utiliser l'argent
A11: 289 | B11: 65 | C11: CADEMA 1 | D11: AO | E11: NON | F11: - | G11: - | H11: 10 | I11: C1 | J11: C1 | K11: EL ANZIZE SALIM | L11: Hamada | M11: 0639 22 81 28 | N11: elsalimhamada@hotmail.com | O11: 024 076 531 00011 | P11: Mamoudzou | Q11: 976_M_209 | R11: 413 | S11: 46877 | T11: GM_515_YL | U11: 45012 | V11: =2024-YEAR(U11) -> 1 | W11: 9 PLACES | Z11: 2023 | AA11: OUI | AB11: 2023 | AD11: OUI | AE11: 10959 | AF11: G | AG11: _ | AH11: NON | AI11: NON | AJ11: NON | AK11: NON | AL11: OUI | AM11: 2022/198 | AN11: 510 | AO11: 43466 | AP11: 250 | AS11: 8 | AT11: Rue de mjinpia | AU11: 97650 | AV11: Mtsangamoudji | AW11: habillage 9 place 2023
A12: 353 | B12: 77 | C12: CADEMA 1 | D12: AO | E12: NON | F12: - | G12: - | H12: 11 | I12: C5 | J12: C16 | K12: HADHURAMI | L12: Makinedine | M12: 0639 94 46 40 | N12: Hadhuramimakinedine976@gmail.com | O12: 054 397 211 00019 | P12: SUD | Q12: 976_S_069 | R12: 150 | S12: 45874 | T12: FZ-411-ZD | U12: 44362 | V12: =2024-YEAR(U12) -> 3 | W12: 9 PLACES | Z12: OUI | AB12: OUI | AD12: OUI | AE12: 49522 | AF12: F | AG12: _ | AH12: OUI | AI12: 2023 | AJ12: NON | AK12: 2022 | AL12: OUI | AM12: 2020/82 | AN12: 510 | AO12: 43466 | AP12: 550 | AS12: 14 | AT12: Rue foundi hamada m'zé | AU12: 97625 | AV12: Kani kéli | AW12: Habillage 2021 aurait 2 véhicules
A13: 385 | B13: 83 | C13: CADEMA 1 | D13: AO | E13: NON | F13: - | G13: - | H13: 12 | J13: C13 | K13: MADI BOINA | L13: Mkidachi | M13: 0639 22 08 67 | N13: madiboinamkidachi@hotmail.com | O13: 500 793 526 00012 | P13: NORD | Q13: 976-N-63 | R13: 985 | S13: 44456 | T13: GS-501-ZK | U13: 45273 | W13: 9 PLACES | X13: NEUF | Y13: pas de vitre | Z13: NON | AA13: OUI | AB13: OUI | AC13: NON | AD13: A venir | AE13: 45248 | AF13: F | AH13: NON | AI13: NON | AJ13: NON | AK13: NON | AL13: NON | AN13: 510 | AO13: 43466 | AP13: 150 | AQ13: NON | AR13: NON | AS13: 27 | AT13: Rue d'andimaka | AU13: 97650 | AV13: Mtsangamouji
A14: 417 | B14: 89 | C14: CADEMA 1 | D14: AO | E14: NON | F14: - | G14: - | H14: 13 | I14: C7 | J14: C3 | K14: MOISSULI HIMIDI | L14: Enly | M14: 0639 94 58 14 | N14: enlymoissuli@gmail.com | O14: 853 881 084 000 18 | P14: NORD | Q14: 976-N-015 | R14: 994 | S14: 44263 | T14: GW-003-JA | U14: 45394 | W14: 9 PLACES | Y14: att May Equip | Z14: NON | AA14: NON | AB14: NON | AC14: NON | AD14: NON | AE14: 47621 | AF14: F | AH14: NON | AI14: NON | AJ14: NON | AK14: NON | AL14: OUI | AN14: 510 | AO14: 43466 | AP14: 200 | AQ14: NON | AR14: NON | AS14: 5 | AT14: Quartier mronobaban sidi , Hamjago | AU14: 97630 | AV14: Mtsamboro | AW14: Il attend sa subvention , justine lui a dit d'aller harceler le CD pour qui'il debloque sa subvention
A15: 97 | B15: 29 | C15: CADEMA 1 | D15: AO | E15: NON | F15: - | G15: - | H15: 14 | I15: soucis de famille | J15: C4 | K15: OUSSENI | L15: Soula | M15: 0639 69 03 87 | N15: soulaousseni415@gmail.com | O15: 066 307 372 000 12 | P15: Centre NORD | Q15: 976-CN-003 | R15: 249 | S15: 43132 | T15: GP_813_HX | U15: 45083 | V15: =2024-YEAR(U15) -> 1 | W15: 9 PLACES | X15: TBE | Z15: 2023 | AA15: OUI | AB15: 2023 | AD15: OUI | AE15: 49496 | AF15: F | AG15: _ | AH15: OUI | AI15: OUI | AJ15: OUI | AK15: OUI | AL15: OUI | AM15: 2021/181 | AN15: 510 | AO15: 43466 | AP15: 300 | AS15: 2 | AT15: Rue mnadzi moja quartier baitil mali | AU15: 97600 | AV15: Mamoudzou | AW15: Pas de voiture
A16: 321 | B16: 71 | C16: CADEMA 1 | D16: AO | E16: NON | F16: - | G16: - | H16: 15 | I16: C8 | J16: C5 | K16: RENE | L16: Assanati | M16: 0639 07 82 51 | O16: 024 065 633 000 18 | P16: NORD | Q16: 976-N-032 | R16: 1337 | S16: 45235 | T16: GR-921-XZ | U16: 45219 | V16: =2024-YEAR(U16) -> 1 | W16: 9 PLACES | Z16: OUI | AB16: NON | AD16: OUI | AE16: 48068 | AF16: F | AG16: _ | AH16: OUI | AI16: 2023 | AJ16: OUI | AK16: 2022 | AN16: 510 | AO16: 44171 | AP16: 150 | AS16: 32 | AT16: Rue bacar tsimanda | AU16: 97650 | AV16: Mtsangamouji
A17: 49 | B17: 20 | C17: CADEMA 1 | E17: NON | F17: NON | G17: NON | H17: 16 | J17: C9 | K17: SANDI | L17: Maanrouf | M17: 0639 40 58 85 | N17: maanroufsandi@laposte.net | O17: 024 069 635 000 19 | P17: Sud | Q17: 976-S-006 | R17: 1184 | S17: 45262 | T17: GW-255-NY | U17: 45406 | W17: 9 PLACES | X17: NEUF | Z17: NON | AA17: OUI | AB17: NON | AC17: NON | AD17: A VENIR | AE17: 46707 | AF17: F | AH17: OUI | AI17: OUI | AJ17: OUI | AK17: 2022 | AL17: NON | AN17: 510 | AO17: 43466 | AP17: 300 | AQ17: NON | AR17: NON | AT17: Quartier ecole primaire | AU17: 97620 | AV17: Chirongui | AW17: Pas habillé en attente rendez-vous mayotte equipement
A18: 177 | B18: 44 | C18: CADEMA 1 | E18: NON | F18: NON | G18: NON | H18: 17 | I18: C2 | J18: C11 | K18: TOUMBOU | L18: Toibourani | M18: 0639 19 14 22 | N18: toumboutoibourani@outlook.fr / anlia.toumbou97620@gmail.com | O18: 024 054 710 000 25 | P18: Mamoudzou | Q18: 976-M-177 | R18: 357 | S18: 45028 | T18: GF_215_AQ | U18: 44624 | V18: =2024-YEAR(U18) -> 2 | W18: 9 PLACES | X18: OK | Z18: 2023 | AA18: OUI | AB18: 2023 | AD18: OUI | AE18: 45992 | AF18: F | AH18: OUI | AI18: OUI | AJ18: NON | AK18: 2022 | AL18: OUI | AM18: 2020/158 | AN18: 510 | AO18: 43466 | AP18: 350 | AS18: 9 | AT18: Rue Bambou | AU18: 97620 | AV18: Chirongui | AW18: Gérant
A22: 17 | B22: 14 | C22: CADEMA 1 | E22: NON | F22: NON | G22: NON | H22: 2 | K22: ACHIRAFFI pas de chauffeur | L22: Assad | M22: 0639 29 01 58 | N22: achiraffis@gmail.com | O22: 024 046 617 000 15 | P22: Mamoudzou | Q22: 976-M-045 | R22: 90 | S22: 46916 | T22: FY-973-FL | U22: 44285 | V22: =2024-YEAR(U22) -> 3 | W22: 9 PLACES | X22: BON | Z22: OUI | AA22: OUI | AB22: OUI | AC22: OUI | AD22: NON | AE22: 49237 | AF22: F | AG22: _ | AH22: OUI | AI22: OUI | AJ22: OUI | AK22: 2022 | AL22: OUI | AM22: 2020/20 | AN22: 510 | AO22: 43466 | AP22: 450 | AQ22: NON | AR22: NON | AS22: 474 | AT22: Route départemental | AU22: 97630 | AV22: M'tsamboro | AW22: a une voiture - Travaille au Sud

Sheet Feuille saisie
A2: TYPE | B2: C15
A3: DATE | B3: 45627
A4: CHAUFFEUR | B4: =VLOOKUP(B2,'Liste chauffeur'!$B$5:$L$20,2,TRUE)&" "&VLOOKUP(B2,'Liste chauffeur'!$B$5:$L$20,3,TRUE) -> HAMADA Babou
I6: Arrêts | K6: ARRIVEE | P6: 8
A7: Lieu de départ | B7: Heure théorique départ | C7: Horaire | D7: Chauffeur | E7: Heure réelle départ | F7: Trajet non effectué | G7: Départ avec plus de 10 mns retard | H7: Nbre personnes montée | I7: - | J7: + | K7: Nbre personnes descente | L7: Heure arrivée finale | M7: Commentaires | N7: Temps Aller | O7: Nbre personnes moyenne | P7: Capacité max | Q7: Taux Fréquentation
A8: =Horaire!A8 -> VAHIBE | B8: =Horaire!B8 -> 0.1875 | C8: =Horaire!C8 -> C2 | D8: =VLOOKUP(C8,'Liste chauffeur'!$B$5:$L$20,2,TRUE)&" "&VLOOKUP(C8,'Liste chauffeur'!$B$5:$L$20,3,TRUE) -> BINA HALADI Bina | F8: =COUNTBLANK(E8) -> 1 | N8: =IF(F8=1,"",L8-E8) | O8: =H8+J8-I8 -> 0 | P8: =IF(F8=1,0,P$6) -> 0 | Q8: =IF(P8=0,0,O8/P8) -> 0
A9: =Horaire!A9 -> VAHIBE | B9: =Horaire!B9 -> 0.19444444 | C9: =Horaire!C9 -> C1 | D9: =VLOOKUP(C9,'Liste chauffeur'!$B$5:$L$20,2,TRUE)&" "&VLOOKUP(C9,'Liste chauffeur'!$B$5:$L$20,3,TRUE) -> EL ANZIZE SALIM Hamada | F9: =COUNTBLANK(E9) -> 1 | N9: =IF(F9=1,"",L9-E9) | O9: =H9+J9-I9 -> 0 | P9: =IF(F9=1,0,P$6) -> 0 | Q9: =IF(P9=0,0,O9/P9) -> 0
A10: =Horaire!A10 -> VAHIBE | B10: =Horaire!B10 -> 0.20138889 | C10: =Horaire!C10 -> C3 | D10: =VLOOKUP(C10,'Liste chauffeur'!$B$5:$L$20,2,TRUE)&" "&VLOOKUP(C10,'Liste chauffeur'!$B$5:$L$20,3,TRUE) -> ABDOU MINIHADJI Amada | F10: =COUNTBLANK(E10) -> 1 | N10: =IF(F10=1,"",L10-E10) | O10: =H10+J10-I10 -> 0 | P10: =IF(F10=1,0,P$6) -> 0 | Q10: =IF(P10=0,0,O10/P10) -> 0
A11: =Horaire!A11 -> PASSAMAINTY | B11: =Horaire!B11 -> 0.20138889 | C11: =Horaire!C11 -> C2 | D11: =VLOOKUP(C11,'Liste chauffeur'!$B$5:$L$20,2,TRUE)&" "&VLOOKUP(C11,'Liste chauffeur'!$B$5:$L$20,3,TRUE) -> BINA HALADI Bina | F11: =COUNTBLANK(E11) -> 1 | N11: =IF(F11=1,"",L11-E11) | O11: =H11+J11-I11 -> 0 | P11: =IF(F11=1,0,P$6) -> 0 | Q11: =IF(P11=0,0,O11/P11) -> 0
A12: =Horaire!A12 -> VAHIBE | B12: =Horaire!B12 -> 0.20833333 | C12: =Horaire!C12 -> C4 | D12: =VLOOKUP(C12,'Liste chauffeur'!$B$5:$L$20,2,TRUE)&" "&VLOOKUP(C12,'Liste chauffeur'!$B$5:$L$20,3,TRUE) -> TOUMBOU Toibourani | F12: =COUNTBLANK(E12) -> 1 | N12: =IF(F12=1,"",L12-E12) | O12: =H12+J12-I12 -> 0 | P12: =IF(F12=1,0,P$6) -> 0 | Q12: =IF(P12=0,0,O12/P12) -> 0
A13: =Horaire!A13 -> PASSAMAINTY | B13: =Horaire!B13 -> 0.20833333 | C13: =Horaire!C13 -> C1 | D13: =VLOOKUP(C13,'Liste chauffeur'!$B$5:$L$20,2,TRUE)&" "&VLOOKUP(C13,'Liste chauffeur'!$B$5:$L$20,3,TRUE) -> EL ANZIZE SALIM Hamada | F13: =COUNTBLANK(E13) -> 1 | N13: =IF(F13=1,"",L13-E13) | O13: =H13+J13-I13 -> 0 | P13: =IF(F13=1,0,P$6) -> 0 | Q13: =IF(P13=0,0,O13/P13) -> 0
A14: =Horaire!A14 -> VAHIBE 2 | B14: =Horaire!B14 -> 0.20833333 | C14: =Horaire!C14 -> C11 | D14: =VLOOKUP(C14,'Liste chauffeur'!$B$5:$L$20,2,TRUE)&" "&VLOOKUP(C14,'Liste chauffeur'!$B$5:$L$20,3,TRUE) -> MADI BOINA Mkidachi | F14: =COUNTBLANK(E14) -> 1 | N14: =IF(F14=1,"",L14-E14) | O14: =H14+J14-I14 -> 0 | P14: =IF(F14=1,0,P$6) -> 0 | Q14: =IF(P14=0,0,O14/P14) -> 0
A15: =Horaire!A15 -> VAHIBE | B15: =Horaire!B15 -> 0.21527778 | C15: =Horaire!C15 -> C2 | D15: =VLOOKUP(C15,'Liste chauffeur'!$B$5:$L$20,2,TRUE)&" "&VLOOKUP(C15,'Liste chauffeur'!$B$5:$L$20,3,TRUE) -> BINA HALADI Bina | F15: =COUNTBLANK(E15) -> 1 | N15: =IF(F15=1,"",L15-E15) | O15: =H15+J15-I15 -> 0 | P15: =IF(F15=1,0,P$6) -> 0 | Q15: =IF(P15=0,0,O15/P15) -> 0
A16: =Horaire!A16 -> VAHIBE 2 | B16: =Horaire!B16 -> 0.21527778 | C16: =Horaire!C16 -> C8 | D16: =VLOOKUP(C16,'Liste chauffeur'!$B$5:$L$20,2,TRUE)&" "&VLOOKUP(C16,'Liste chauffeur'!$B$5:$L$20,3,TRUE) -> HADHURAMI Makinedine | F16: =COUNTBLANK(E16) -> 1 | N16: =IF(F16=1,"",L16-E16) | O16: =H16+J16-I16 -> 0 | P16: =IF(F16=1,0,P$6) -> 0 | Q16: =IF(P16=0,0,O16/P16) -> 0
A17: =Horaire!A17 -> PASSAMAINTY | B17: =Horaire!B17 -> 0.21527778 | C17: =Horaire!C17 -> C3 | D17: =VLOOKUP(C17,'Liste chauffeur'!$B$5:$L$20,2,TRUE)&" "&VLOOKUP(C17,'Liste chauffeur'!$B$5:$L$20,3,TRUE) -> ABDOU MINIHADJI Amada | F17: =COUNTBLANK(E17) -> 1 | N17: =IF(F17=1,"",L17-E17) | O17: =H17+J17-I17 -> 0 | P17: =IF(F17=1,0,P$6) -> 0 | Q17: =IF(P17=0,0,O17/P17) -> 0
A18: =Horaire!A18 -> VAHIBE | B18: =Horaire!B18 -> 0.22222222 | C18: =Horaire!C18 -> C1 | D18: =VLOOKUP(C18,'Liste chauffeur'!$B$5:$L$20,2,TRUE)&" "&VLOOKUP(C18,'Liste chauffeur'!$B$5:$L$20,3,TRUE) -> EL ANZIZE SALIM Hamada | F18: =COUNTBLANK(E18) -> 1 | O18: =H18+J18-I18 -> 0 | P18: =IF(F18=1,0,P$6) -> 0 | Q18: =IF(P18=0,0,O18/P18) -> 0
A19: =Horaire!A19 -> VAHIBE 2 | B19: =Horaire!B19 -> 0.22222222 | C19: =Horaire!C19 -> C9 | D19: =VLOOKUP(C19,'Liste chauffeur'!$B$5:$L$20,2,TRUE)&" "&VLOOKUP(C19,'Liste chauffeur'!$B$5:$L$20,3,TRUE) -> SANDI Maanrouf | F19: =COUNTBLANK(E19) -> 1 | N19: =IF(F19=1,"",L19-E19) | O19: =H19+J19-I19 -> 0 | P19: =IF(F19=1,0,P$6) -> 0 | Q19: =IF(P19=0,0,O19/P19) -> 0
A20: =Horaire!A20 -> PASSAMAINTY | B20: =Horaire!B20 -> 0.22222222 | C20: =Horaire!C20 -> C4 | D20: =VLOOKUP(C20,'Liste chauffeur'!$B$5:$L$20,2,TRUE)&" "&VLOOKUP(C20,'Liste chauffeur'!$B$5:$L$20,3,TRUE) -> TOUMBOU Toibourani | F20: =COUNTBLANK(E20) -> 1 | N20: =IF(F20=1,"",L20-E20) | O20: =H20+J20-I20 -> 0 | P20: =IF(F20=1,0,P$6) -> 0 | Q20: =IF(P20=0,0,O20/P20) -> 0
A21: =Horaire!A21 -> PASSAMAINTY | B21: =Horaire!B21 -> 0.22222222 | C21: =Horaire!C21 -> C11 | D21: =VLOOKUP(C21,'Liste chauffeur'!$B$5:$L$20,2,TRUE)&" "&VLOOKUP(C21,'Liste chauffeur'!$B$5:$L$20,3,TRUE) -> MADI BOINA Mkidachi | F21: =COUNTBLANK(E21) -> 1 | N21: =IF(F21=1,"",L21-E21) | O21: =H21+J21-I21 -> 0 | P21: =IF(F21=1,0,P$6) -> 0 | Q21: =IF(P21=0,0,O21/P21) -> 0
A22: =Horaire!A22 -> VAHIBE | B22: =Horaire!B22 -> 0.22916667 | C22: =Horaire!C22 -> C3 | D22: =VLOOKUP(C22,'Liste chauffeur'!$B$5:$L$20,2,TRUE)&" "&VLOOKUP(C22,'Liste chauffeur'!$B$5:$L$20,3,TRUE) -> ABDOU MINIHADJI Amada | F22: =COUNTBLANK(E22) -> 1 | N22: =IF(F22=1,"",L22-E22) | O22: =H22+J22-I22 -> 0 | P22: =IF(F22=1,0,P$6) -> 0 | Q22: =IF(P22=0,0,O22/P22) -> 0
A23: =Horaire!A23 -> VAHIBE 2 | B23: =Horaire!B23 -> 0.22916667 | C23: =Horaire!C23 -> C10 | D23: =VLOOKUP(C23,'Liste chauffeur'!$B$5:$L$20,2,TRUE)&" "&VLOOKUP(C23,'Liste chauffeur'!$B$5:$L$20,3,TRUE) -> ISSIHAKA M'Changama | F23: =COUNTBLANK(E23) -> 1 | N23: =IF(F23=1,"",L23-E23) | O23: =H23+J23-I23 -> 0 | P23: =IF(F23=1,0,P$6) -> 0 | Q23: =IF(P23=0,0,O23/P23) -> 0
A24: =Horaire!A24 -> PASSAMAINTY | B24: =Horaire!B24 -> 0.22916667 | C24: =Horaire!C24 -> C2 | D24: =VLOOKUP(C24,'Liste chauffeur'!$B$5:$L$20,2,TRUE)&" "&VLOOKUP(C24,'Liste chauffeur'!$B$5:$L$20,3,TRUE) -> BINA HALADI Bina | F24: =COUNTBLANK(E24) -> 1 | N24: =IF(F24=1,"",L24-E24) | O24: =H24+J24-I24 -> 0 | P24: =IF(F24=1,0,P$6) -> 0 | Q24: =IF(P24=0,0,O24/P24) -> 0
A25: =Horaire!A25 -> PASSAMAINTY | B25: =Horaire!B25 -> 0.22916667 | C25: =Horaire!C25 -> C8 | D25: =VLOOKUP(C25,'Liste chauffeur'!$B$5:$L$20,2,TRUE)&" "&VLOOKUP(C25,'Liste chauffeur'!$B$5:$L$20,3,TRUE) -> HADHURAMI Makinedine | F25: =COUNTBLANK(E25) -> 1 | O25: =H25+J25-I25 -> 0 | P25: =IF(F25=1,0,P$6) -> 0 | Q25: =IF(P25=0,0,O25/P25) -> 0
A26: =Horaire!A26 -> VAHIBE | B26: =Horaire!B26 -> 0.23611111 | C26: =Horaire!C26 -> C4 | D26: =VLOOKUP(C26,'Liste chauffeur'!$B$5:$L$20,2,TRUE)&" "&VLOOKUP(C26,'Liste chauffeur'!$B$5:$L$20,3,TRUE) -> TOUMBOU Toibourani | F26: =COUNTBLANK(E26) -> 1 | N26: =IF(F26=1,"",L26-E26) | O26: =H26+J26-I26 -> 0 | P26: =IF(F26=1,0,P$6) -> 0 | Q26: =IF(P26=0,0,O26/P26) -> 0
A27: =Horaire!A27 -> VAHIBE 2 | B27: =Horaire!B27 -> 0.23611111 | C27: =Horaire!C27 -> C11 | D27: =VLOOKUP(C27,'Liste chauffeur'!$B$5:$L$20,2,TRUE)&" "&VLOOKUP(C27,'Liste chauffeur'!$B$5:$L$20,3,TRUE) -> MADI BOINA Mkidachi | F27: =COUNTBLANK(E27) -> 1 | N27: =IF(F27=1,"",L27-E27) | O27: =H27+J27-I27 -> 0 | P27: =IF(F27=1,0,P$6) -> 0 | Q27: =IF(P27=0,0,O27/P27) -> 0
A28: =Horaire!A28 -> PASSAMAINTY | B28: =Horaire!B28 -> 0.23611111 | C28: =Horaire!C28 -> C1 | D28: =VLOOKUP(C28,'Liste chauffeur'!$B$5:$L$20,2,TRUE)&" "&VLOOKUP(C28,'Liste chauffeur'!$B$5:$L$20,3,TRUE) -> EL ANZIZE SALIM Hamada | F28: =COUNTBLANK(E28) -> 1 | N28: =IF(F28=1,"",L28-E28) | O28: =H28+J28-I28 -> 0 | P28: =IF(F28=1,0,P$6) -> 0 | Q28: =IF(P28=0,0,O28/P28) -> 0
A29: =Horaire!A29 -> PASSAMAINTY | B29: =Horaire!B29 -> 0.23611111 | C29: =Horaire!C29 -> C9 | D29: =VLOOKUP(C29,'Liste chauffeur'!$B$5:$L$20,2,TRUE)&" "&VLOOKUP(C29,'Liste chauffeur'!$B$5:$L$20,3,TRUE) -> SANDI Maanrouf | F29: =COUNTBLANK(E29) -> 1 | N29: =IF(F29=1,"",L29-E29) | O29: =H29+J29-I29 -> 0 | P29: =IF(F29=1,0,P$6) -> 0 | Q29: =IF(P29=0,0,O29/P29) -> 0
A30: =Horaire!A30 -> VAHIBE | B30: =Horaire!B30 -> 0.24305556 | C30: =Horaire!C30 -> C2 | D30: =VLOOKUP(C30,'Liste chauffeur'!$B$5:$L$20,2,TRUE)&" "&VLOOKUP(C30,'Liste chauffeur'!$B$5:$L$20,3,TRUE) -> BINA HALADI Bina | F30: =COUNTBLANK(E30) -> 1 | N30: =IF(F30=1,"",L30-E30) | O30: =H30+J30-I30 -> 0 | P30: =IF(F30=1,0,P$6) -> 0 | Q30: =IF(P30=0,0,O30/P30) -> 0
A31: =Horaire!A31 -> VAHIBE 2 | B31: =Horaire!B31 -> 0.24305556 | C31: =Horaire!C31 -> C8 | D31: =VLOOKUP(C31,'Liste chauffeur'!$B$5:$L$20,2,TRUE)&" "&VLOOKUP(C31,'Liste chauffeur'!$B$5:$L$20,3,TRUE) -> HADHURAMI Makinedine | F31: =COUNTBLANK(E31) -> 1 | N31: =IF(F31=1,"",L31-E31) | O31: =H31+J31-I31 -> 0 | P31: =IF(F31=1,0,P$6) -> 0 | Q31: =IF(P31=0,0,O31/P31) -> 0
A32: =Horaire!A32 -> PASSAMAINTY | B32: =Horaire!B32 -> 0.24305556 | C32: =Horaire!C32 -> C3 | D32: =VLOOKUP(C32,'Liste chauffeur'!$B$5:$L$20,2,TRUE)&" "&VLOOKUP(C32,'Liste chauffeur'!$B$5:$L$20,3,TRUE) -> ABDOU MINIHADJI Amada | F32: =COUNTBLANK(E32) -> 1 | O32: =H32+J32-I32 -> 0 | P32: =IF(F32=1,0,P$6) -> 0 | Q32: =IF(P32=0,0,O32/P32) -> 0
A33: =Horaire!A33 -> PASSAMAINTY | B33: =Horaire!B33 -> 0.24305556 | C33: =Horaire!C33 -> C10 | D33: =VLOOKUP(C33,'Liste chauffeur'!$B$5:$L$20,2,TRUE)&" "&VLOOKUP(C33,'Liste chauffeur'!$B$5:$L$20,3,TRUE) -> ISSIHAKA M'Changama | F33: =COUNTBLANK(E33) -> 1 | N33: =IF(F33=1,"",L33-E33) | O33: =H33+J33-I33 -> 0 | P33: =IF(F33=1,0,P$6) -> 0 | Q33: =IF(P33=0,0,O33/P33) -> 0
A34: =Horaire!A34 -> VAHIBE | B34: =Horaire!B34 -> 0.25 | C34: =Horaire!C34 -> C1 | D34: =VLOOKUP(C34,'Liste chauffeur'!$B$5:$L$20,2,TRUE)&" "&VLOOKUP(C34,'Liste chauffeur'!$B$5:$L$20,3,TRUE) -> EL ANZIZE SALIM Hamada | F34: =COUNTBLANK(E34) -> 1 | N34: =IF(F34=1,"",L34-E34) | O34: =H34+J34-I34 -> 0 | P34: =IF(F34=1,0,P$6) -> 0 | Q34: =IF(P34=0,0,O34/P34) -> 0
A35: =Horaire!A35 -> VAHIBE 2 | B35: =Horaire!B35 -> 0.25 | C35: =Horaire!C35 -> C9 | D35: =VLOOKUP(C35,'Liste chauffeur'!$B$5:$L$20,2,TRUE)&" "&VLOOKUP(C35,'Liste chauffeur'!$B$5:$L$20,3,TRUE) -> SANDI Maanrouf | F35: =COUNTBLANK(E35) -> 1 | N35: =IF(F35=1,"",L35-E35) | O35: =H35+J35-I35 -> 0 | P35: =IF(F35=1,0,P$6) -> 0 | Q35: =IF(P35=0,0,O35/P35) -> 0
A36: =Horaire!A36 -> PASSAMAINTY | B36: =Horaire!B36 -> 0.25 | C36: =Horaire!C36 -> C5 | D36: =VLOOKUP(C36,'Liste chauffeur'!$B$5:$L$20,2,TRUE)&" "&VLOOKUP(C36,'Liste chauffeur'!$B$5:$L$20,3,TRUE) -> AHAMADI Bacar Raenmouddine | F36: =COUNTBLANK(E36) -> 1 | N36: =IF(F36=1,"",L36-E36) | O36: =H36+J36-I36 -> 0 | P36: =IF(F36=1,0,P$6) -> 0 | Q36: =IF(P36=0,0,O36/P36) -> 0
A37: =Horaire!A37 -> PASSAMAINTY | B37: =Horaire!B37 -> 0.25 | C37: =Horaire!C37 -> C12 | D37: =VLOOKUP(C37,'Liste chauffeur'!$B$5:$L$20,2,TRUE)&" "&VLOOKUP(C37,'Liste chauffeur'!$B$5:$L$20,3,TRUE) -> ALILOIFFA Said Siradj | F37: =COUNTBLANK(E37) -> 1 | N37: =IF(F37=1,"",L37-E37) | O37: =H37+J37-I37 -> 0 | P37: =IF(F37=1,0,P$6) -> 0 | Q37: =IF(P37=0,0,O37/P37) -> 0
A38: =Horaire!A38 -> VAHIBE | B38: =Horaire!B38 -> 0.25694444 | C38: =Horaire!C38 -> C3 | D38: =VLOOKUP(C38,'Liste chauffeur'!$B$5:$L$20,2,TRUE)&" "&VLOOKUP(C38,'Liste chauffeur'!$B$5:$L$20,3,TRUE) -> ABDOU MINIHADJI Amada | F38: =COUNTBLANK(E38) -> 1 | N38: =IF(F38=1,"",L38-E38) | O38: =H38+J38-I38 -> 0 | P38: =IF(F38=1,0,P$6) -> 0 | Q38: =IF(P38=0,0,O38/P38) -> 0
A39: =Horaire!A39 -> VAHIBE 2 | B39: =Horaire!B39 -> 0.25694444 | C39: =Horaire!C39 -> C10 | D39: =VLOOKUP(C39,'Liste chauffeur'!$B$5:$L$20,2,TRUE)&" "&VLOOKUP(C39,'Liste chauffeur'!$B$5:$L$20,3,TRUE) -> ISSIHAKA M'Changama | F39: =COUNTBLANK(E39) -> 1 | N39: =IF(F39=1,"",L39-E39) | O39: =H39+J39-I39 -> 0 | P39: =IF(F39=1,0,P$6) -> 0 | Q39: =IF(P39=0,0,O39/P39) -> 0
A40: =Horaire!A40 -> PASSAMAINTY | B40: =Horaire!B40 -> 0.25694444 | C40: =Horaire!C40 -> C4 | D40: =VLOOKUP(C40,'Liste chauffeur'!$B$5:$L$20,2,TRUE)&" "&VLOOKUP(C40,'Liste chauffeur'!$B$5:$L$20,3,TRUE) -> TOUMBOU Toibourani | F40: =COUNTBLANK(E40) -> 1 | N40: =IF(F40=1,"",L40-E40) | O40: =H40+J40-I40 -> 0 | P40: =IF(F40=1,0,P$6) -> 0 | Q40: =IF(P40=0,0,O40/P40) -> 0
A41: =Horaire!A41 -> PASSAMAINTY | B41: =Horaire!B41 -> 0.25694444 | C41: =Horaire!C41 -> C11 | D41: =VLOOKUP(C41,'Liste chauffeur'!$B$5:$L$20,2,TRUE)&" "&VLOOKUP(C41,'Liste chauffeur'!$B$5:$L$20,3,TRUE) -> MADI BOINA Mkidachi | F41: =COUNTBLANK(E41) -> 1 | N41: =IF(F41=1,"",L41-E41) | O41: =H41+J41-I41 -> 0 | P41: =IF(F41=1,0,P$6) -> 0 | Q41: =IF(P41=0,0,O41/P41) -> 0
A42: =Horaire!A42 -> VAHIBE | B42: =Horaire!B42 -> 0.26388889 | C42: =Horaire!C42 -> C5 | D42: =VLOOKUP(C42,'Liste chauffeur'!$B$5:$L$20,2,TRUE)&" "&VLOOKUP(C42,'Liste chauffeur'!$B$5:$L$20,3,TRUE) -> AHAMADI Bacar Raenmouddine | F42: =COUNTBLANK(E42) -> 1 | N42: =IF(F42=1,"",L42-E42) | O42: =H42+J42-I42 -> 0 | P42: =IF(F42=1,0,P$6) -> 0 | Q42: =IF(P42=0,0,O42/P42) -> 0
...

Sheet Feuille saisie samedi
A2: TYPE | B2: C11
A3: DATE | B3: 45627
A4: CHAUFFEUR | B4: =VLOOKUP(B2,'Liste chauffeur'!$B$5:$L$20,2,TRUE)&" "&VLOOKUP(B2,'Liste chauffeur'!$B$5:$L$20,3,TRUE) -> MADI BOINA Mkidachi
I6: Arrêt 1 | M6: Arrêt 2 | Q6: Arrêt 3 | W6: ARRIVEE | AA6: 8
B7: Heure théorique départ | C7: Horaire | D7: Chauffeur | E7: Heure réelle départ | F7: Trajet non effectué | G7: Départ avec plus de 10 mns retard | H7: Nbre personnes montée | I7: - | J7: + | K7: Heure arrivée arrêt 1 | L7: Délai | M7: - | N7: + | O7: Heure arrivée arrêt 2 | P7: Délai | Q7: - | R7: + | S7: Heure arrivée arrêt 3 | T7: Délai | U7: Nbre personnes descente | W7: Heure arrivée finale | X7: Commentaires | Y7: Temps Aller | Z7: Nbre personnes moyenne | AA7: Capacité max | AB7: Taux Fréquentation
A8: ='Horaire samedi'!A8 -> VAHIBE | B8: ='Horaire samedi'!B8 -> 0.25 | C8: ='Horaire samedi'!C8 -> C11 | D8: =VLOOKUP(C8,'Liste chauffeur'!$B$5:$L$20,2,TRUE)&" "&VLOOKUP(C8,'Liste chauffeur'!$B$5:$L$20,3,TRUE) -> MADI BOINA Mkidachi | F8: =COUNTBLANK(E8) -> 1 | Y8: =IF(F8=1,"",W8-E8) | Z8: =H8+J8-I8 -> 0 | AA8: =IF(F8=1,0,AA$6) -> 0 | AB8: =IF(AA8=0,0,Z8/AA8) -> 0
A9: ='Horaire samedi'!A9 -> VAHIBE | B9: ='Horaire samedi'!B9 -> 0.27083333 | C9: ='Horaire samedi'!C9 -> C9 | D9: =VLOOKUP(C9,'Liste chauffeur'!$B$5:$L$20,2,TRUE)&" "&VLOOKUP(C9,'Liste chauffeur'!$B$5:$L$20,3,TRUE) -> SANDI Maanrouf | F9: =COUNTBLANK(E9) -> 1 | Y9: =IF(F9=1,"",W9-E9) | Z9: =H9+J9-I9 -> 0 | AA9: =IF(F9=1,0,AA$6) -> 0 | AB9: =IF(AA9=0,0,Z9/AA9) -> 0
A10: ='Horaire samedi'!A10 -> PASSAMAINTY | B10: ='Horaire samedi'!B10 -> 0.27083333 | C10: ='Horaire samedi'!C10 -> C11 | D10: =VLOOKUP(C10,'Liste chauffeur'!$B$5:$L$20,2,TRUE)&" "&VLOOKUP(C10,'Liste chauffeur'!$B$5:$L$20,3,TRUE) -> MADI BOINA Mkidachi | F10: =COUNTBLANK(E10) -> 1 | Y10: =IF(F10=1,"",W10-E10) | Z10: =H10+J10-I10 -> 0 | AA10: =IF(F10=1,0,AA$6) -> 0 | AB10: =IF(AA10=0,0,Z10/AA10) -> 0
A11: ='Horaire samedi'!A11 -> VAHIBE | B11: ='Horaire samedi'!B11 -> 0.29166667 | C11: ='Horaire samedi'!C11 -> C11 | D11: =VLOOKUP(C11,'Liste chauffeur'!$B$5:$L$20,2,TRUE)&" "&VLOOKUP(C11,'Liste chauffeur'!$B$5:$L$20,3,TRUE) -> MADI BOINA Mkidachi | F11: =COUNTBLANK(E11) -> 1 | Y11: =IF(F11=1,"",W11-E11) | Z11: =H11+J11-I11 -> 0 | AA11: =IF(F11=1,0,AA$6) -> 0 | AB11: =IF(AA11=0,0,Z11/AA11) -> 0
A12: ='Horaire samedi'!A12 -> PASSAMAINTY | B12: ='Horaire samedi'!B12 -> 0.29166667 | C12: ='Horaire samedi'!C12 -> C9 | D12: =VLOOKUP(C12,'Liste chauffeur'!$B$5:$L$20,2,TRUE)&" "&VLOOKUP(C12,'Liste chauffeur'!$B$5:$L$20,3,TRUE) -> SANDI Maanrouf | F12: =COUNTBLANK(E12) -> 1 | L12: =K12-E12 -> 0 | P12: =O12-K12 -> 0 | T12: =S12-O12 -> 0 | V12: =IF(H12-I12+J12-M12+N12-Q12+R12=U12,"OK",H12-I12+J12-M12+N12-Q12+R12-U12) -> OK | Y12: =IF(F12=1,"",W12-E12) | Z12: =H12+J12-I12 -> 0 | AA12: =IF(F12=1,0,AA$6) -> 0 | AB12: =IF(AA12=0,0,Z12/AA12) -> 0
A13: ='Horaire samedi'!A13 -> VAHIBE | B13: ='Horaire samedi'!B13 -> 0.3125 | C13: ='Horaire samedi'!C13 -> C11 | D13: =VLOOKUP(C13,'Liste chauffeur'!$B$5:$L$20,2,TRUE)&" "&VLOOKUP(C13,'Liste chauffeur'!$B$5:$L$20,3,TRUE) -> MADI BOINA Mkidachi | F13: =COUNTBLANK(E13) -> 1 | L13: =K13-E13 -> 0 | P13: =O13-K13 -> 0 | T13: =S13-O13 -> 0 | Y13: =IF(F13=1,"",W13-E13) | Z13: =H13+J13-I13 -> 0 | AA13: =IF(F13=1,0,AA$6) -> 0 | AB13: =IF(AA13=0,0,Z13/AA13) -> 0
A14: ='Horaire samedi'!A14 -> PASSAMAINTY | B14: ='Horaire samedi'!B14 -> 0.3125 | C14: ='Horaire samedi'!C14 -> C9 | D14: =VLOOKUP(C14,'Liste chauffeur'!$B$5:$L$20,2,TRUE)&" "&VLOOKUP(C14,'Liste chauffeur'!$B$5:$L$20,3,TRUE) -> SANDI Maanrouf | F14: =COUNTBLANK(E14) -> 1 | L14: =K14-E14 -> 0 | P14: =O14-K14 -> 0 | T14: =S14-O14 -> 0 | Y14: =IF(F14=1,"",W14-E14) | Z14: =H14+J14-I14 -> 0 | AA14: =IF(F14=1,0,AA$6) -> 0 | AB14: =IF(AA14=0,0,Z14/AA14) -> 0
A15: ='Horaire samedi'!A15 -> VAHIBE | B15: ='Horaire samedi'!B15 -> 0.33333333 | C15: ='Horaire samedi'!C15 -> C9 | D15: =VLOOKUP(C15,'Liste chauffeur'!$B$5:$L$20,2,TRUE)&" "&VLOOKUP(C15,'Liste chauffeur'!$B$5:$L$20,3,TRUE) -> SANDI Maanrouf | F15: =COUNTBLANK(E15) -> 1 | L15: =K15-E15 -> 0 | P15: =O15-K15 -> 0 | T15: =S15-O15 -> 0 | Y15: =IF(F15=1,"",W15-E15) | Z15: =H15+J15-I15 -> 0 | AA15: =IF(F15=1,0,AA$6) -> 0 | AB15: =IF(AA15=0,0,Z15/AA15) -> 0
A16: ='Horaire samedi'!A16 -> PASSAMAINTY | B16: ='Horaire samedi'!B16 -> 0.33333333 | C16: ='Horaire samedi'!C16 -> C11 | D16: =VLOOKUP(C16,'Liste chauffeur'!$B$5:$L$20,2,TRUE)&" "&VLOOKUP(C16,'Liste chauffeur'!$B$5:$L$20,3,TRUE) -> MADI BOINA Mkidachi | F16: =COUNTBLANK(E16) -> 1 | L16: =K16-E16 -> 0 | P16: =O16-K16 -> 0 | T16: =S16-O16 -> 0 | V16: =IF(H16-I16+J16-M16+N16-Q16+R16=U16,"OK",H16-I16+J16-M16+N16-Q16+R16-U16) -> OK | Y16: =IF(F16=1,"",W16-E16) | Z16: =H16+J16-I16 -> 0 | AA16: =IF(F16=1,0,AA$6) -> 0 | AB16: =IF(AA16=0,0,Z16/AA16) -> 0
A17: ='Horaire samedi'!A17 -> VAHIBE | B17: ='Horaire samedi'!B17 -> 0.375 | C17: ='Horaire samedi'!C17 -> C11 | D17: =VLOOKUP(C17,'Liste chauffeur'!$B$5:$L$20,2,TRUE)&" "&VLOOKUP(C17,'Liste chauffeur'!$B$5:$L$20,3,TRUE) -> MADI BOINA Mkidachi | F17: =COUNTBLANK(E17) -> 1 | L17: =K17-E17 -> 0 | P17: =O17-K17 -> 0 | T17: =S17-O17 -> 0 | V17: =IF(H17-I17+J17-M17+N17-Q17+R17=U17,"OK",H17-I17+J17-M17+N17-Q17+R17-U17) -> OK | Y17: =IF(F17=1,"",W17-E17) | Z17: =H17+J17-I17 -> 0 | AA17: =IF(F17=1,0,AA$6) -> 0 | AB17: =IF(AA17=0,0,Z17/AA17) -> 0
A18: ='Horaire samedi'!A18 -> PASSAMAINTY | B18: ='Horaire samedi'!B18 -> 0.375 | C18: ='Horaire samedi'!C18 -> C9 | D18: =VLOOKUP(C18,'Liste chauffeur'!$B$5:$L$20,2,TRUE)&" "&VLOOKUP(C18,'Liste chauffeur'!$B$5:$L$20,3,TRUE) -> SANDI Maanrouf | F18: =COUNTBLANK(E18) -> 1 | Z18: =H18+J18-I18 -> 0 | AA18: =IF(F18=1,0,AA$6) -> 0 | AB18: =IF(AA18=0,0,Z18/AA18) -> 0
A19: ='Horaire samedi'!A19 -> VAHIBE | B19: ='Horaire samedi'!B19 -> 0.39583333 | C19: ='Horaire samedi'!C19 -> C9 | D19: =VLOOKUP(C19,'Liste chauffeur'!$B$5:$L$20,2,TRUE)&" "&VLOOKUP(C19,'Liste chauffeur'!$B$5:$L$20,3,TRUE) -> SANDI Maanrouf | F19: =COUNTBLANK(E19) -> 1 | L19: =K19-E19 -> 0 | P19: =O19-K19 -> 0 | T19: =S19-O19 -> 0 | V19: =IF(H19-I19+J19-M19+N19-Q19+R19=U19,"OK",H19-I19+J19-M19+N19-Q19+R19-U19) -> OK | Y19: =IF(F19=1,"",W19-E19) | Z19: =H19+J19-I19 -> 0 | AA19: =IF(F19=1,0,AA$6) -> 0 | AB19: =IF(AA19=0,0,Z19/AA19) -> 0
A20: ='Horaire samedi'!A20 -> PASSAMAINTY | B20: ='Horaire samedi'!B20 -> 0.39583333 | C20: ='Horaire samedi'!C20 -> C11 | D20: =VLOOKUP(C20,'Liste chauffeur'!$B$5:$L$20,2,TRUE)&" "&VLOOKUP(C20,'Liste chauffeur'!$B$5:$L$20,3,TRUE) -> MADI BOINA Mkidachi | F20: =COUNTBLANK(E20) -> 1 | L20: =K20-E20 -> 0 | P20: =O20-K20 -> 0 | T20: =S20-O20 -> 0 | V20: =IF(H20-I20+J20-M20+N20-Q20+R20=U20,"OK",H20-I20+J20-M20+N20-Q20+R20-U20) -> OK | Y20: =IF(F20=1,"",W20-E20) | Z20: =H20+J20-I20 -> 0 | AA20: =IF(F20=1,0,AA$6) -> 0 | AB20: =IF(AA20=0,0,Z20/AA20) -> 0
A21: ='Horaire samedi'!A21 -> VAHIBE | B21: ='Horaire samedi'!B21 -> 0.41666667 | C21: ='Horaire samedi'!C21 -> C11 | D21: =VLOOKUP(C21,'Liste chauffeur'!$B$5:$L$20,2,TRUE)&" "&VLOOKUP(C21,'Liste chauffeur'!$B$5:$L$20,3,TRUE) -> MADI BOINA Mkidachi | F21: =COUNTBLANK(E21) -> 1 | L21: =K21-E21 -> 0 | P21: =O21-K21 -> 0 | T21: =S21-O21 -> 0 | V21: =IF(H21-I21+J21-M21+N21-Q21+R21=U21,"OK",H21-I21+J21-M21+N21-Q21+R21-U21) -> OK | Y21: =IF(F21=1,"",W21-E21) | Z21: =H21+J21-I21 -> 0 | AA21: =IF(F21=1,0,AA$6) -> 0 | AB21: =IF(AA21=0,0,Z21/AA21) -> 0
A22: ='Horaire samedi'!A22 -> PASSAMAINTY | B22: ='Horaire samedi'!B22 -> 0.41666667 | C22: ='Horaire samedi'!C22 -> C9 | D22: =VLOOKUP(C22,'Liste chauffeur'!$B$5:$L$20,2,TRUE)&" "&VLOOKUP(C22,'Liste chauffeur'!$B$5:$L$20,3,TRUE) -> SANDI Maanrouf | F22: =COUNTBLANK(E22) -> 1 | L22: =K22-E22 -> 0 | P22: =O22-K22 -> 0 | T22: =S22-O22 -> 0 | V22: =IF(H22-I22+J22-M22+N22-Q22+R22=U22,"OK",H22-I22+J22-M22+N22-Q22+R22-U22) -> OK | Y22: =IF(F22=1,"",W22-E22) | Z22: =H22+J22-I22 -> 0 | AA22: =IF(F22=1,0,AA$6) -> 0 | AB22: =IF(AA22=0,0,Z22/AA22) -> 0
A23: ='Horaire samedi'!A23 -> VAHIBE | B23: ='Horaire samedi'!B23 -> 0.4375 | C23: ='Horaire samedi'!C23 -> C9 | D23: =VLOOKUP(C23,'Liste chauffeur'!$B$5:$L$20,2,TRUE)&" "&VLOOKUP(C23,'Liste chauffeur'!$B$5:$L$20,3,TRUE) -> SANDI Maanrouf | F23: =COUNTBLANK(E23) -> 1 | L23: =K23-E23 -> 0 | P23: =O23-K23 -> 0 | T23: =S23-O23 -> 0 | V23: =IF(H23-I23+J23-M23+N23-Q23+R23=U23,"OK",H23-I23+J23-M23+N23-Q23+R23-U23) -> OK | Y23: =IF(F23=1,"",W23-E23) | Z23: =H23+J23-I23 -> 0 | AA23: =IF(F23=1,0,AA$6) -> 0 | AB23: =IF(AA23=0,0,Z23/AA23) -> 0
A24: ='Horaire samedi'!A24 -> PASSAMAINTY | B24: ='Horaire samedi'!B24 -> 0.4375 | C24: ='Horaire samedi'!C24 -> C11 | D24: =VLOOKUP(C24,'Liste chauffeur'!$B$5:$L$20,2,TRUE)&" "&VLOOKUP(C24,'Liste chauffeur'!$B$5:$L$20,3,TRUE) -> MADI BOINA Mkidachi | F24: =COUNTBLANK(E24) -> 1 | L24: =K24-E24 -> 0 | P24: =O24-K24 -> 0 | T24: =S24-O24 -> 0 | V24: =IF(H24-I24+J24-M24+N24-Q24+R24=U24,"OK",H24-I24+J24-M24+N24-Q24+R24-U24) -> OK | Y24: =IF(F24=1,"",W24-E24) | Z24: =H24+J24-I24 -> 0 | AA24: =IF(F24=1,0,AA$6) -> 0 | AB24: =IF(AA24=0,0,Z24/AA24) -> 0
A25: ='Horaire samedi'!A25 -> VAHIBE | B25: ='Horaire samedi'!B25 -> 0.45833333 | C25: ='Horaire samedi'!C25 -> C11 | D25: =VLOOKUP(C25,'Liste chauffeur'!$B$5:$L$20,2,TRUE)&" "&VLOOKUP(C25,'Liste chauffeur'!$B$5:$L$20,3,TRUE) -> MADI BOINA Mkidachi | F25: =COUNTBLANK(E25) -> 1 | Z25: =H25+J25-I25 -> 0 | AA25: =IF(F25=1,0,AA$6) -> 0 | AB25: =IF(AA25=0,0,Z25/AA25) -> 0
A26: ='Horaire samedi'!A26 -> PASSAMAINTY | B26: ='Horaire samedi'!B26 -> 0.45833333 | C26: ='Horaire samedi'!C26 -> C9 | D26: =VLOOKUP(C26,'Liste chauffeur'!$B$5:$L$20,2,TRUE)&" "&VLOOKUP(C26,'Liste chauffeur'!$B$5:$L$20,3,TRUE) -> SANDI Maanrouf | F26: =COUNTBLANK(E26) -> 1 | L26: =K26-E26 -> 0 | P26: =O26-K26 -> 0 | T26: =S26-O26 -> 0 | V26: =IF(H26-I26+J26-M26+N26-Q26+R26=U26,"OK",H26-I26+J26-M26+N26-Q26+R26-U26) -> OK | Y26: =IF(F26=1,"",W26-E26) | Z26: =H26+J26-I26 -> 0 | AA26: =IF(F26=1,0,AA$6) -> 0 | AB26: =IF(AA26=0,0,Z26/AA26) -> 0
A27: ='Horaire samedi'!A27 -> VAHIBE | B27: ='Horaire samedi'!B27 -> 0.47916667 | C27: ='Horaire samedi'!C27 -> C9 | D27: =VLOOKUP(C27,'Liste chauffeur'!$B$5:$L$20,2,TRUE)&" "&VLOOKUP(C27,'Liste chauffeur'!$B$5:$L$20,3,TRUE) -> SANDI Maanrouf | F27: =COUNTBLANK(E27) -> 1 | L27: =K27-E27 -> 0 | P27: =O27-K27 -> 0 | T27: =S27-O27 -> 0 | V27: =IF(H27-I27+J27-M27+N27-Q27+R27=U27,"OK",H27-I27+J27-M27+N27-Q27+R27-U27) -> OK | Y27: =IF(F27=1,"",W27-E27) | Z27: =H27+J27-I27 -> 0 | AA27: =IF(F27=1,0,AA$6) -> 0 | AB27: =IF(AA27=0,0,Z27/AA27) -> 0
A28: ='Horaire samedi'!A28 -> PASSAMAINTY | B28: ='Horaire samedi'!B28 -> 0.47916667 | C28: ='Horaire samedi'!C28 -> C11 | D28: =VLOOKUP(C28,'Liste chauffeur'!$B$5:$L$20,2,TRUE)&" "&VLOOKUP(C28,'Liste chauffeur'!$B$5:$L$20,3,TRUE) -> MADI BOINA Mkidachi | F28: =COUNTBLANK(E28) -> 1 | L28: =K28-E28 -> 0 | P28: =O28-K28 -> 0 | T28: =S28-O28 -> 0 | V28: =IF(H28-I28+J28-M28+N28-Q28+R28=U28,"OK",H28-I28+J28-M28+N28-Q28+R28-U28) -> OK | Y28: =IF(F28=1,"",W28-E28) | Z28: =H28+J28-I28 -> 0 | AA28: =IF(F28=1,0,AA$6) -> 0 | AB28: =IF(AA28=0,0,Z28/AA28) -> 0
A29: ='Horaire samedi'!A29 -> VAHIBE | B29: ='Horaire samedi'!B29 -> 0.5 | C29: ='Horaire samedi'!C29 -> C11 | D29: =VLOOKUP(C29,'Liste chauffeur'!$B$5:$L$20,2,TRUE)&" "&VLOOKUP(C29,'Liste chauffeur'!$B$5:$L$20,3,TRUE) -> MADI BOINA Mkidachi | F29: =COUNTBLANK(E29) -> 1 | L29: =K29-E29 -> 0 | P29: =O29-K29 -> 0 | T29: =S29-O29 -> 0 | V29: =IF(H29-I29+J29-M29+N29-Q29+R29=U29,"OK",H29-I29+J29-M29+N29-Q29+R29-U29) -> OK | Y29: =IF(F29=1,"",W29-E29) | Z29: =H29+J29-I29 -> 0 | AA29: =IF(F29=1,0,AA$6) -> 0 | AB29: =IF(AA29=0,0,Z29/AA29) -> 0
A30: ='Horaire samedi'!A30 -> PASSAMAINTY | B30: ='Horaire samedi'!B30 -> 0.5 | C30: ='Horaire samedi'!C30 -> C9 | D30: =VLOOKUP(C30,'Liste chauffeur'!$B$5:$L$20,2,TRUE)&" "&VLOOKUP(C30,'Liste chauffeur'!$B$5:$L$20,3,TRUE) -> SANDI Maanrouf | F30: =COUNTBLANK(E30) -> 1 | L30: =K30-E30 -> 0 | P30: =O30-K30 -> 0 | T30: =S30-O30 -> 0 | V30: =IF(H30-I30+J30-M30+N30-Q30+R30=U30,"OK",H30-I30+J30-M30+N30-Q30+R30-U30) -> OK | Y30: =IF(F30=1,"",W30-E30) | Z30: =H30+J30-I30 -> 0 | AA30: =IF(F30=1,0,AA$6) -> 0 | AB30: =IF(AA30=0,0,Z30/AA30) -> 0
B31: ST1 | F31: =SUM(F8:F30) -> 23 | G31: =SUM(G8:G30) -> 0 | Y31: =AVERAGE(Y8:Y30) -> #DIV/0! | Z31: =SUM(Z8:Z30) -> 0 | AA31: =SUM(AA8:AA30) -> 0 | AB31: =IF(AA31=0,0,Z31/AA31) -> 0
A32: ='Horaire samedi'!A31 -> VAHIBE | B32: ='Horaire samedi'!B31 -> 0.52083333 | C32: ='Horaire samedi'!C31 -> C9 | D32: =VLOOKUP(C32,'Liste chauffeur'!$B$5:$L$20,2,TRUE)&" "&VLOOKUP(C32,'Liste chauffeur'!$B$5:$L$20,3,TRUE) -> SANDI Maanrouf | F32: =COUNTBLANK(E32) -> 1 | L32: =K32-E32 -> 0 | P32: =O32-K32 -> 0 | T32: =S32-O32 -> 0 | V32: =IF(H32-I32+J32-M32+N32-Q32+R32=U32,"OK",H32-I32+J32-M32+N32-Q32+R32-U32) -> OK | Y32: =IF(F32=1,"",W32-E32) | Z32: =H32+J32-I32 -> 0 | AA32: =IF(F32=1,0,AA$6) -> 0 | AB32: =IF(AA32=0,0,Z32/AA32) -> 0
A33: ='Horaire samedi'!A32 -> PASSAMAINTY | B33: ='Horaire samedi'!B32 -> 0.52083333 | C33: ='Horaire samedi'!C32 -> C11 | D33: =VLOOKUP(C33,'Liste chauffeur'!$B$5:$L$20,2,TRUE)&" "&VLOOKUP(C33,'Liste chauffeur'!$B$5:$L$20,3,TRUE) -> MADI BOINA Mkidachi | F33: =COUNTBLANK(E33) -> 1 | Z33: =H33+J33-I33 -> 0 | AA33: =IF(F33=1,0,AA$6) -> 0 | AB33: =IF(AA33=0,0,Z33/AA33) -> 0
A34: ='Horaire samedi'!A33 -> VAHIBE | B34: ='Horaire samedi'!B33 -> 0.54166667 | C34: ='Horaire samedi'!C33 -> C11 | D34: =VLOOKUP(C34,'Liste chauffeur'!$B$5:$L$20,2,TRUE)&" "&VLOOKUP(C34,'Liste chauffeur'!$B$5:$L$20,3,TRUE) -> MADI BOINA Mkidachi | F34: =COUNTBLANK(E34) -> 1 | L34: =K34-E34 -> 0 | P34: =O34-K34 -> 0 | T34: =S34-O34 -> 0 | V34: =IF(H34-I34+J34-M34+N34-Q34+R34=U34,"OK",H34-I34+J34-M34+N34-Q34+R34-U34) -> OK | Y34: =IF(F34=1,"",W34-E34) | Z34: =H34+J34-I34 -> 0 | AA34: =IF(F34=1,0,AA$6) -> 0 | AB34: =IF(AA34=0,0,Z34/AA34) -> 0
A35: ='Horaire samedi'!A34 -> PASSAMAINTY | B35: ='Horaire samedi'!B34 -> 0.54166667 | C35: ='Horaire samedi'!C34 -> C9 | D35: =VLOOKUP(C35,'Liste chauffeur'!$B$5:$L$20,2,TRUE)&" "&VLOOKUP(C35,'Liste chauffeur'!$B$5:$L$20,3,TRUE) -> SANDI Maanrouf | F35: =COUNTBLANK(E35) -> 1 | L35: =K35-E35 -> 0 | V35: =IF(H35-I35+J35-M35+N35-Q35+R35=U35,"OK",H35-I35+J35-M35+N35-Q35+R35-U35) -> OK | Y35: =IF(F35=1,"",W35-E35) | Z35: =H35+J35-I35 -> 0 | AA35: =IF(F35=1,0,AA$6) -> 0 | AB35: =IF(AA35=0,0,Z35/AA35) -> 0
A36: ='Horaire samedi'!A35 -> VAHIBE | B36: ='Horaire samedi'!B35 -> 0.5625 | C36: ='Horaire samedi'!C35 -> C9 | D36: =VLOOKUP(C36,'Liste chauffeur'!$B$5:$L$20,2,TRUE)&" "&VLOOKUP(C36,'Liste chauffeur'!$B$5:$L$20,3,TRUE) -> SANDI Maanrouf | F36: =COUNTBLANK(E36) -> 1 | L36: =K36-E36 -> 0 | V36: =IF(H36-I36+J36-M36+N36-Q36+R36=U36,"OK",H36-I36+J36-M36+N36-Q36+R36-U36) -> OK | Y36: =IF(F36=1,"",W36-E36) | Z36: =H36+J36-I36 -> 0 | AA36: =IF(F36=1,0,AA$6) -> 0 | AB36: =IF(AA36=0,0,Z36/AA36) -> 0
A37: ='Horaire samedi'!A36 -> PASSAMAINTY | B37: ='Horaire samedi'!B36 -> 0.5625 | C37: ='Horaire samedi'!C36 -> C10 | D37: =VLOOKUP(C37,'Liste chauffeur'!$B$5:$L$20,2,TRUE)&" "&VLOOKUP(C37,'Liste chauffeur'!$B$5:$L$20,3,TRUE) -> ISSIHAKA M'Changama | F37: =COUNTBLANK(E37) -> 1 | L37: =K37-E37 -> 0 | V37: =IF(H37-I37+J37-M37+N37-Q37+R37=U37,"OK",H37-I37+J37-M37+N37-Q37+R37-U37) -> OK | Y37: =IF(F37=1,"",W37-E37) | Z37: =H37+J37-I37 -> 0 | AA37: =IF(F37=1,0,AA$6) -> 0 | AB37: =IF(AA37=0,0,Z37/AA37) -> 0
A38: ='Horaire samedi'!A37 -> VAHIBE | B38: ='Horaire samedi'!B37 -> 0.58333333 | C38: ='Horaire samedi'!C37 -> C10 | D38: =VLOOKUP(C38,'Liste chauffeur'!$B$5:$L$20,2,TRUE)&" "&VLOOKUP(C38,'Liste chauffeur'!$B$5:$L$20,3,TRUE) -> ISSIHAKA M'Changama | F38: =COUNTBLANK(E38) -> 1 | L38: =K38-E38 -> 0 | V38: =IF(H38-I38+J38-M38+N38-Q38+R38=U38,"OK",H38-I38+J38-M38+N38-Q38+R38-U38) -> OK | Y38: =IF(F38=1,"",W38-E38) | Z38: =H38+J38-I38 -> 0 | AA38: =IF(F38=1,0,AA$6) -> 0 | AB38: =IF(AA38=0,0,Z38/AA38) -> 0
A39: ='Horaire samedi'!A38 -> PASSAMAINTY | B39: ='Horaire samedi'!B38 -> 0.58333333 | C39: ='Horaire samedi'!C38 -> C8 | D39: =VLOOKUP(C39,'Liste chauffeur'!$B$5:$L$20,2,TRUE)&" "&VLOOKUP(C39,'Liste chauffeur'!$B$5:$L$20,3,TRUE) -> HADHURAMI Makinedine | F39: =COUNTBLANK(E39) -> 1 | L39: =K39-E39 -> 0 | V39: =IF(H39-I39+J39-M39+N39-Q39+R39=U39,"OK",H39-I39+J39-M39+N39-Q39+R39-U39) -> OK | Y39: =IF(F39=1,"",W39-E39) | Z39: =H39+J39-I39 -> 0 | AA39: =IF(F39=1,0,AA$6) -> 0 | AB39: =IF(AA39=0,0,Z39/AA39) -> 0
A40: ='Horaire samedi'!A39 -> VAHIBE | B40: ='Horaire samedi'!B39 -> 0.60416667 | C40: ='Horaire samedi'!C39 -> C8 | D40: =VLOOKUP(C40,'Liste chauffeur'!$B$5:$L$20,2,TRUE)&" "&VLOOKUP(C40,'Liste chauffeur'!$B$5:$L$20,3,TRUE) -> HADHURAMI Makinedine | F40: =COUNTBLANK(E40) -> 1 | L40: =K40-E40 -> 0 | V40: =IF(H40-I40+J40-M40+N40-Q40+R40=U40,"OK",H40-I40+J40-M40+N40-Q40+R40-U40) -> OK | Y40: =IF(F40=1,"",W40-E40) | Z40: =H40+J40-I40 -> 0 | AA40: =IF(F40=1,0,AA$6) -> 0 | AB40: =IF(AA40=0,0,Z40/AA40) -> 0
A41: ='Horaire samedi'!A40 -> PASSAMAINTY | B41: ='Horaire samedi'!B40 -> 0.60416667 | C41: ='Horaire samedi'!C40 -> C10 | D41: =VLOOKUP(C41,'Liste chauffeur'!$B$5:$L$20,2,TRUE)&" "&VLOOKUP(C41,'Liste chauffeur'!$B$5:$L$20,3,TRUE) -> ISSIHAKA M'Changama | F41: =COUNTBLANK(E41) -> 1 | L41: =K41-E41 -> 0 | V41: =IF(H41-I41+J41-M41+N41-Q41+R41=U41,"OK",H41-I41+J41-M41+N41-Q41+R41-U41) -> OK | Y41: =IF(F41=1,"",W41-E41) | Z41: =H41+J41-I41 -> 0 | AA41: =IF(F41=1,0,AA$6) -> 0 | AB41: =IF(AA41=0,0,Z41/AA41) -> 0
A42: ='Horaire samedi'!A41 -> VAHIBE | B42: ='Horaire samedi'!B41 -> 0.625 | C42: ='Horaire samedi'!C41 -> C10 | D42: =VLOOKUP(C42,'Liste chauffeur'!$B$5:$L$20,2,TRUE)&" "&VLOOKUP(C42,'Liste chauffeur'!$B$5:$L$20,3,TRUE) -> ISSIHAKA M'Changama | F42: =COUNTBLANK(E42) -> 1 | L42: =K42-E42 -> 0 | V42: =IF(H42-I42+J42-M42+N42-Q42+R42=U42,"OK",H42-I42+J42-M42+N42-Q42+R42-U42) -> OK | Y42: =IF(F42=1,"",W42-E42) | Z42: =H42+J42-I42 -> 0 | AA42: =IF(F42=1,0,AA$6) -> 0 | AB42: =IF(AA42=0,0,Z42/AA42) -> 0
...

Sheet Feuille saisie dimanche 1
A2: TYPE | B2: C8
A3: DATE | B3: 45627
A4: CHAUFFEUR | B4: =VLOOKUP(B2,'Liste chauffeur'!$B$5:$L$20,2,TRUE)&" "&VLOOKUP(B2,'Liste chauffeur'!$B$5:$L$20,3,TRUE) -> HADHURAMI Makinedine
I6: Arrêt 1 | M6: Arrêt 2 | Q6: Arrêt 3 | W6: ARRIVEE | AA6: 8
B7: Heure théorique départ | C7: Horaire | D7: Chauffeur | E7: Heure réelle départ | F7: Trajet non effectué | G7: Départ avec plus de 10 mns retard | H7: Nbre personnes montée | I7: - | J7: + | K7: Heure arrivée arrêt 1 | L7: Délai | M7: - | N7: + | O7: Heure arrivée arrêt 2 | P7: Délai | Q7: - | R7: + | S7: Heure arrivée arrêt 3 | T7: Délai | U7: Nbre personnes descente | W7: Heure arrivée finale | X7: Commentaires | Y7: Temps Aller | Z7: Nbre personnes moyenne | AA7: Capacité max | AB7: Taux Fréquentation
A8: ='Horaire dimanche1'!A8 -> VAHIBE | B8: ='Horaire dimanche1'!B8 -> 0.33333333 | C8: ='Horaire dimanche1'!C8 -> C5 | D8: =VLOOKUP(C8,'Liste chauffeur'!$B$5:$L$20,2,TRUE)&" "&VLOOKUP(C8,'Liste chauffeur'!$B$5:$L$20,3,TRUE) -> AHAMADI Bacar Raenmouddine | F8: =COUNTBLANK(E8) -> 1 | Y8: =IF(F8=1,"",W8-E8) | Z8: =H8+J8-I8 -> 0 | AA8: =IF(F8=1,0,AA$6) -> 0 | AB8: =IF(AA8=0,0,Z8/AA8) -> 0
A9: ='Horaire dimanche1'!A9 -> PASSAMAINTY | B9: ='Horaire dimanche1'!B9 -> 0.35416667 | C9: ='Horaire dimanche1'!C9 -> C5 | D9: =VLOOKUP(C9,'Liste chauffeur'!$B$5:$L$20,2,TRUE)&" "&VLOOKUP(C9,'Liste chauffeur'!$B$5:$L$20,3,TRUE) -> AHAMADI Bacar Raenmouddine | F9: =COUNTBLANK(E9) -> 1 | Y9: =IF(F9=1,"",W9-E9) | Z9: =H9+J9-I9 -> 0 | AA9: =IF(F9=1,0,AA$6) -> 0 | AB9: =IF(AA9=0,0,Z9/AA9) -> 0
A10: ='Horaire dimanche1'!A10 -> VAHIBE | B10: ='Horaire dimanche1'!B10 -> 0.375 | C10: ='Horaire dimanche1'!C10 -> C5 | D10: =VLOOKUP(C10,'Liste chauffeur'!$B$5:$L$20,2,TRUE)&" "&VLOOKUP(C10,'Liste chauffeur'!$B$5:$L$20,3,TRUE) -> AHAMADI Bacar Raenmouddine | F10: =COUNTBLANK(E10) -> 1 | Y10: =IF(F10=1,"",W10-E10) | Z10: =H10+J10-I10 -> 0 | AA10: =IF(F10=1,0,AA$6) -> 0 | AB10: =IF(AA10=0,0,Z10/AA10) -> 0
A11: ='Horaire dimanche1'!A11 -> PASSAMAINTY | B11: ='Horaire dimanche1'!B11 -> 0.39583333 | C11: ='Horaire dimanche1'!C11 -> C5 | D11: =VLOOKUP(C11,'Liste chauffeur'!$B$5:$L$20,2,TRUE)&" "&VLOOKUP(C11,'Liste chauffeur'!$B$5:$L$20,3,TRUE) -> AHAMADI Bacar Raenmouddine | F11: =COUNTBLANK(E11) -> 1 | Y11: =IF(F11=1,"",W11-E11) | Z11: =H11+J11-I11 -> 0 | AA11: =IF(F11=1,0,AA$6) -> 0 | AB11: =IF(AA11=0,0,Z11/AA11) -> 0
A12: ='Horaire dimanche1'!A12 -> VAHIBE | B12: ='Horaire dimanche1'!B12 -> 0.41666667 | C12: ='Horaire dimanche1'!C12 -> C5 | D12: =VLOOKUP(C12,'Liste chauffeur'!$B$5:$L$20,2,TRUE)&" "&VLOOKUP(C12,'Liste chauffeur'!$B$5:$L$20,3,TRUE) -> AHAMADI Bacar Raenmouddine | F12: =COUNTBLANK(E12) -> 1 | L12: =K12-E12 -> 0 | P12: =O12-K12 -> 0 | T12: =S12-O12 -> 0 | V12: =IF(H12-I12+J12-M12+N12-Q12+R12=U12,"OK",H12-I12+J12-M12+N12-Q12+R12-U12) -> OK | Y12: =IF(F12=1,"",W12-E12) | Z12: =H12+J12-I12 -> 0 | AA12: =IF(F12=1,0,AA$6) -> 0 | AB12: =IF(AA12=0,0,Z12/AA12) -> 0
A13: ='Horaire dimanche1'!A13 -> PASSAMAINTY | B13: ='Horaire dimanche1'!B13 -> 0.4375 | C13: ='Horaire dimanche1'!C13 -> C5 | D13: =VLOOKUP(C13,'Liste chauffeur'!$B$5:$L$20,2,TRUE)&" "&VLOOKUP(C13,'Liste chauffeur'!$B$5:$L$20,3,TRUE) -> AHAMADI Bacar Raenmouddine | F13: =COUNTBLANK(E13) -> 1 | L13: =K13-E13 -> 0 | P13: =O13-K13 -> 0 | T13: =S13-O13 -> 0 | Y13: =IF(F13=1,"",W13-E13) | Z13: =H13+J13-I13 -> 0 | AA13: =IF(F13=1,0,AA$6) -> 0 | AB13: =IF(AA13=0,0,Z13/AA13) -> 0
A14: ='Horaire dimanche1'!A14 -> VAHIBE | B14: ='Horaire dimanche1'!B14 -> 0.45833333 | C14: ='Horaire dimanche1'!C14 -> C5 | D14: =VLOOKUP(C14,'Liste chauffeur'!$B$5:$L$20,2,TRUE)&" "&VLOOKUP(C14,'Liste chauffeur'!$B$5:$L$20,3,TRUE) -> AHAMADI Bacar Raenmouddine | F14: =COUNTBLANK(E14) -> 1 | L14: =K14-E14 -> 0 | P14: =O14-K14 -> 0 | T14: =S14-O14 -> 0 | Y14: =IF(F14=1,"",W14-E14) | Z14: =H14+J14-I14 -> 0 | AA14: =IF(F14=1,0,AA$6) -> 0 | AB14: =IF(AA14=0,0,Z14/AA14) -> 0
A15: ='Horaire dimanche1'!A15 -> PASSAMAINTY | B15: ='Horaire dimanche1'!B15 -> 0.47916667 | C15: ='Horaire dimanche1'!C15 -> C5 | D15: =VLOOKUP(C15,'Liste chauffeur'!$B$5:$L$20,2,TRUE)&" "&VLOOKUP(C15,'Liste chauffeur'!$B$5:$L$20,3,TRUE) -> AHAMADI Bacar Raenmouddine | F15: =COUNTBLANK(E15) -> 1 | L15: =K15-E15 -> 0 | P15: =O15-K15 -> 0 | T15: =S15-O15 -> 0 | Y15: =IF(F15=1,"",W15-E15) | Z15: =H15+J15-I15 -> 0 | AA15: =IF(F15=1,0,AA$6) -> 0 | AB15: =IF(AA15=0,0,Z15/AA15) -> 0
A16: ='Horaire dimanche1'!A16 -> VAHIBE | B16: ='Horaire dimanche1'!B16 -> 0.5 | C16: ='Horaire dimanche1'!C16 -> C5 | D16: =VLOOKUP(C16,'Liste chauffeur'!$B$5:$L$20,2,TRUE)&" "&VLOOKUP(C16,'Liste chauffeur'!$B$5:$L$20,3,TRUE) -> AHAMADI Bacar Raenmouddine | F16: =COUNTBLANK(E16) -> 1 | L16: =K16-E16 -> 0 | P16: =O16-K16 -> 0 | T16: =S16-O16 -> 0 | V16: =IF(H16-I16+J16-M16+N16-Q16+R16=U16,"OK",H16-I16+J16-M16+N16-Q16+R16-U16) -> OK | Y16: =IF(F16=1,"",W16-E16) | Z16: =H16+J16-I16 -> 0 | AA16: =IF(F16=1,0,AA$6) -> 0 | AB16: =IF(AA16=0,0,Z16/AA16) -> 0
B17: ST1 | F17: =SUM(F8:F16) -> 9 | G17: =SUM(G8:G16) -> 0 | Y17: =AVERAGE(Y8:Y16) -> #DIV/0! | Z17: =SUM(Z8:Z16) -> 0 | AA17: =SUM(AA8:AA16) -> 0 | AB17: =IF(AA17=0,0,Z17/AA17) -> 0
A18: ='Horaire dimanche1'!A17 -> PASSAMAINTY | B18: ='Horaire dimanche1'!B17 -> 0.52083333 | C18: ='Horaire dimanche1'!C17 -> C5 | D18: =VLOOKUP(C18,'Liste chauffeur'!$B$5:$L$20,2,TRUE)&" "&VLOOKUP(C18,'Liste chauffeur'!$B$5:$L$20,3,TRUE) -> AHAMADI Bacar Raenmouddine | F18: =COUNTBLANK(E18) -> 1 | L18: =K18-E18 -> 0 | P18: =O18-K18 -> 0 | T18: =S18-O18 -> 0 | V18: =IF(H18-I18+J18-M18+N18-Q18+R18=U18,"OK",H18-I18+J18-M18+N18-Q18+R18-U18) -> OK | Y18: =IF(F18=1,"",W18-E18) | Z18: =H18+J18-I18 -> 0 | AA18: =IF(F18=1,0,AA$6) -> 0 | AB18: =IF(AA18=0,0,Z18/AA18) -> 0
A19: ='Horaire dimanche1'!A18 -> VAHIBE | B19: ='Horaire dimanche1'!B18 -> 0.54166667 | C19: ='Horaire dimanche1'!C18 -> C5 | D19: =VLOOKUP(C19,'Liste chauffeur'!$B$5:$L$20,2,TRUE)&" "&VLOOKUP(C19,'Liste chauffeur'!$B$5:$L$20,3,TRUE) -> AHAMADI Bacar Raenmouddine | F19: =COUNTBLANK(E19) -> 1 | Z19: =H19+J19-I19 -> 0 | AA19: =IF(F19=1,0,AA$6) -> 0 | AB19: =IF(AA19=0,0,Z19/AA19) -> 0
A20: ='Horaire dimanche1'!A19 -> PASSAMAINTY | B20: ='Horaire dimanche1'!B19 -> 0.5625 | C20: ='Horaire dimanche1'!C19 -> C5 | D20: =VLOOKUP(C20,'Liste chauffeur'!$B$5:$L$20,2,TRUE)&" "&VLOOKUP(C20,'Liste chauffeur'!$B$5:$L$20,3,TRUE) -> AHAMADI Bacar Raenmouddine | F20: =COUNTBLANK(E20) -> 1 | L20: =K20-E20 -> 0 | P20: =O20-K20 -> 0 | T20: =S20-O20 -> 0 | V20: =IF(H20-I20+J20-M20+N20-Q20+R20=U20,"OK",H20-I20+J20-M20+N20-Q20+R20-U20) -> OK | Y20: =IF(F20=1,"",W20-E20) | Z20: =H20+J20-I20 -> 0 | AA20: =IF(F20=1,0,AA$6) -> 0 | AB20: =IF(AA20=0,0,Z20/AA20) -> 0
A21: ='Horaire dimanche1'!A20 -> VAHIBE | B21: ='Horaire dimanche1'!B20 -> 0.58333333 | C21: ='Horaire dimanche1'!C20 -> C8 | D21: =VLOOKUP(C21,'Liste chauffeur'!$B$5:$L$20,2,TRUE)&" "&VLOOKUP(C21,'Liste chauffeur'!$B$5:$L$20,3,TRUE) -> HADHURAMI Makinedine | F21: =COUNTBLANK(E21) -> 1 | L21: =K21-E21 -> 0 | P21: =O21-K21 -> 0 | T21: =S21-O21 -> 0 | V21: =IF(H21-I21+J21-M21+N21-Q21+R21=U21,"OK",H21-I21+J21-M21+N21-Q21+R21-U21) -> OK | Y21: =IF(F21=1,"",W21-E21) | Z21: =H21+J21-I21 -> 0 | AA21: =IF(F21=1,0,AA$6) -> 0 | AB21: =IF(AA21=0,0,Z21/AA21) -> 0
A22: ='Horaire dimanche1'!A21 -> PASSAMAINTY | B22: ='Horaire dimanche1'!B21 -> 0.60416667 | C22: ='Horaire dimanche1'!C21 -> C8 | D22: =VLOOKUP(C22,'Liste chauffeur'!$B$5:$L$20,2,TRUE)&" "&VLOOKUP(C22,'Liste chauffeur'!$B$5:$L$20,3,TRUE) -> HADHURAMI Makinedine | F22: =COUNTBLANK(E22) -> 1 | L22: =K22-E22 -> 0 | P22: =O22-K22 -> 0 | T22: =S22-O22 -> 0 | V22: =IF(H22-I22+J22-M22+N22-Q22+R22=U22,"OK",H22-I22+J22-M22+N22-Q22+R22-U22) -> OK | Y22: =IF(F22=1,"",W22-E22) | Z22: =H22+J22-I22 -> 0 | AA22: =IF(F22=1,0,AA$6) -> 0 | AB22: =IF(AA22=0,0,Z22/AA22) -> 0
A23: ='Horaire dimanche1'!A22 -> VAHIBE | B23: ='Horaire dimanche1'!B22 -> 0.625 | C23: ='Horaire dimanche1'!C22 -> C8 | D23: =VLOOKUP(C23,'Liste chauffeur'!$B$5:$L$20,2,TRUE)&" "&VLOOKUP(C23,'Liste chauffeur'!$B$5:$L$20,3,TRUE) -> HADHURAMI Makinedine | F23: =COUNTBLANK(E23) -> 1 | L23: =K23-E23 -> 0 | P23: =O23-K23 -> 0 | T23: =S23-O23 -> 0 | V23: =IF(H23-I23+J23-M23+N23-Q23+R23=U23,"OK",H23-I23+J23-M23+N23-Q23+R23-U23) -> OK | Y23: =IF(F23=1,"",W23-E23) | Z23: =H23+J23-I23 -> 0 | AA23: =IF(F23=1,0,AA$6) -> 0 | AB23: =IF(AA23=0,0,Z23/AA23) -> 0
A24: ='Horaire dimanche1'!A23 -> PASSAMAINTY | B24: ='Horaire dimanche1'!B23 -> 0.64583333 | C24: ='Horaire dimanche1'!C23 -> C8 | D24: =VLOOKUP(C24,'Liste chauffeur'!$B$5:$L$20,2,TRUE)&" "&VLOOKUP(C24,'Liste chauffeur'!$B$5:$L$20,3,TRUE) -> HADHURAMI Makinedine | F24: =COUNTBLANK(E24) -> 1 | L24: =K24-E24 -> 0 | P24: =O24-K24 -> 0 | T24: =S24-O24 -> 0 | V24: =IF(H24-I24+J24-M24+N24-Q24+R24=U24,"OK",H24-I24+J24-M24+N24-Q24+R24-U24) -> OK | Y24: =IF(F24=1,"",W24-E24) | Z24: =H24+J24-I24 -> 0 | AA24: =IF(F24=1,0,AA$6) -> 0 | AB24: =IF(AA24=0,0,Z24/AA24) -> 0
A25: ='Horaire dimanche1'!A24 -> VAHIBE | B25: ='Horaire dimanche1'!B24 -> 0.66666667 | C25: ='Horaire dimanche1'!C24 -> C8 | D25: =VLOOKUP(C25,'Liste chauffeur'!$B$5:$L$20,2,TRUE)&" "&VLOOKUP(C25,'Liste chauffeur'!$B$5:$L$20,3,TRUE) -> HADHURAMI Makinedine | F25: =COUNTBLANK(E25) -> 1 | L25: =K25-E25 -> 0 | P25: =O25-K25 -> 0 | T25: =S25-O25 -> 0 | V25: =IF(H25-I25+J25-M25+N25-Q25+R25=U25,"OK",H25-I25+J25-M25+N25-Q25+R25-U25) -> OK | Y25: =IF(F25=1,"",W25-E25) | Z25: =H25+J25-I25 -> 0 | AA25: =IF(F25=1,0,AA$6) -> 0 | AB25: =IF(AA25=0,0,Z25/AA25) -> 0
A26: ='Horaire dimanche1'!A25 -> PASSAMAINTY | B26: ='Horaire dimanche1'!B25 -> 0.6875 | C26: ='Horaire dimanche1'!C25 -> C8 | D26: =VLOOKUP(C26,'Liste chauffeur'!$B$5:$L$20,2,TRUE)&" "&VLOOKUP(C26,'Liste chauffeur'!$B$5:$L$20,3,TRUE) -> HADHURAMI Makinedine | F26: =COUNTBLANK(E26) -> 1 | Z26: =H26+J26-I26 -> 0 | AA26: =IF(F26=1,0,AA$6) -> 0 | AB26: =IF(AA26=0,0,Z26/AA26) -> 0
A27: ='Horaire dimanche1'!A26 -> VAHIBE | B27: ='Horaire dimanche1'!B26 -> 0.70833333 | C27: ='Horaire dimanche1'!C26 -> C8 | D27: =VLOOKUP(C27,'Liste chauffeur'!$B$5:$L$20,2,TRUE)&" "&VLOOKUP(C27,'Liste chauffeur'!$B$5:$L$20,3,TRUE) -> HADHURAMI Makinedine | F27: =COUNTBLANK(E27) -> 1 | L27: =K27-E27 -> 0 | P27: =O27-K27 -> 0 | T27: =S27-O27 -> 0 | V27: =IF(H27-I27+J27-M27+N27-Q27+R27=U27,"OK",H27-I27+J27-M27+N27-Q27+R27-U27) -> OK | Y27: =IF(F27=1,"",W27-E27) | Z27: =H27+J27-I27 -> 0 | AA27: =IF(F27=1,0,AA$6) -> 0 | AB27: =IF(AA27=0,0,Z27/AA27) -> 0
A28: ='Horaire dimanche1'!A27 -> PASSAMAINTY | B28: ='Horaire dimanche1'!B27 -> 0.72222222 | C28: ='Horaire dimanche1'!C27 -> C8 | D28: =VLOOKUP(C28,'Liste chauffeur'!$B$5:$L$20,2,TRUE)&" "&VLOOKUP(C28,'Liste chauffeur'!$B$5:$L$20,3,TRUE) -> HADHURAMI Makinedine | F28: =COUNTBLANK(E28) -> 1 | L28: =K28-E28 -> 0 | P28: =O28-K28 -> 0 | T28: =S28-O28 -> 0 | V28: =IF(H28-I28+J28-M28+N28-Q28+R28=U28,"OK",H28-I28+J28-M28+N28-Q28+R28-U28) -> OK | Y28: =IF(F28=1,"",W28-E28) | Z28: =H28+J28-I28 -> 0 | AA28: =IF(F28=1,0,AA$6) -> 0 | AB28: =IF(AA28=0,0,Z28/AA28) -> 0
A29: ='Horaire dimanche1'!A28 -> VAHIBE | B29: ='Horaire dimanche1'!B28 -> 0.74305556 | C29: ='Horaire dimanche1'!C28 -> C8 | D29: =VLOOKUP(C29,'Liste chauffeur'!$B$5:$L$20,2,TRUE)&" "&VLOOKUP(C29,'Liste chauffeur'!$B$5:$L$20,3,TRUE) -> HADHURAMI Makinedine | F29: =COUNTBLANK(E29) -> 1 | L29: =K29-E29 -> 0 | P29: =O29-K29 -> 0 | T29: =S29-O29 -> 0 | V29: =IF(H29-I29+J29-M29+N29-Q29+R29=U29,"OK",H29-I29+J29-M29+N29-Q29+R29-U29) -> OK | Y29: =IF(F29=1,"",W29-E29) | Z29: =H29+J29-I29 -> 0 | AA29: =IF(F29=1,0,AA$6) -> 0 | AB29: =IF(AA29=0,0,Z29/AA29) -> 0
A30: ='Horaire dimanche1'!A29 -> PASSAMAINTY | B30: ='Horaire dimanche1'!B29 -> 0.75694444 | C30: ='Horaire dimanche1'!C29 -> C8 | D30: =VLOOKUP(C30,'Liste chauffeur'!$B$5:$L$20,2,TRUE)&" "&VLOOKUP(C30,'Liste chauffeur'!$B$5:$L$20,3,TRUE) -> HADHURAMI Makinedine | F30: =COUNTBLANK(E30) -> 1 | L30: =K30-E30 -> 0 | P30: =O30-K30 -> 0 | T30: =S30-O30 -> 0 | V30: =IF(H30-I30+J30-M30+N30-Q30+R30=U30,"OK",H30-I30+J30-M30+N30-Q30+R30-U30) -> OK | Y30: =IF(F30=1,"",W30-E30) | Z30: =H30+J30-I30 -> 0 | AA30: =IF(F30=1,0,AA$6) -> 0 | AB30: =IF(AA30=0,0,Z30/AA30) -> 0
B31: ST2 | F31: =SUM(F18:F30) -> 13 | G31: =SUM(G18:G30) -> 0 | Y31: =AVERAGE(Y18:Y30) -> #DIV/0! | Z31: =SUM(Z18:Z30) -> 0 | AA31: =SUM(AA18:AA30) -> 0 | AB31: =IF(AA31=0,0,Z31/AA31) -> 0
B32: ST3 | F32: =F17+F31 -> 22 | G32: =G17+G31 -> 0 | Y32: =AVERAGE(Y8:Y16,Y18:Y30) -> #DIV/0! | Z32: =Z17+Z31 -> 0 | AA32: =AA17+AA31 -> 0 | AB32: =IF(AA32=0,0,Z32/AA32) -> 0
A33: REMPLACEMENT | C33: C | O33: =M33-#REF! -> #REF! | P33: =#REF!+#REF!-#REF! -> #REF!
A34: REMPLACEMENT | C34: C
